Workbook

Sheet Plan de cordes et filage
A1: Plan de cordes du Piano, calcul automatique des sollicitations et des diamètres des cordes basses filées, par Ing. ViGA-FR
A2: Piano : | B2: The Weber AEOLIAN Company New York - Duo Art, cadre 5F, FR6’ 183cm (équivalent 170cm) SN=73211 1918 | U2: Calcul des cordes filées
B3: (marque modèle longueur numéro-de-série année-de-fabrication)
A4: 440 | B4: Hz | C4: Diapason LA3/A4
C5: calcule selon la charge de rupture (CR) mesurée voir tableau de CR
A6: 1 | C6: 1 = calcule en tenant compte de l’augmentation de fréquence des aiguës pour contrer l’inharmonicité | AE6: coef intervalle tempéré
C7: ="Cordes acier par : "&AC61 & ", cordes basses filées de "&Paramètres!D8 -> Cordes acier par : Stephen Paulello France, cordes basses filées de cuivre | O7: tension moyenne par corde | P7: =P8/G8 -> 718.33614 | U7: ="Diamètre fil de trait "&Paramètres!D8 -> Diamètre fil de trait cuivre | AE7: =(AG61/AG49)^(1/12) -> 1.0594871 | AF7: =$AE46*AG$9*SQRT(1+$G46*AG$9^2) -> 369.82191
G8: =SUM(G13:G115) -> 228 | O8: tension totale en Newtons | P8: =SUM(P13:P115) -> 163780.64 | U8: Trait simple | X8: Trait double d2=2*d1 | AE8: inverse | AG8: fréquence réelle octave juste
A9: Fréquence (Hz) | B9: Nom note | C9: Note | D9: Longueur Vibrante (mm) | E9: Ø âme (mm) | F9: Ø total (mm) | G9: Nb cordes | H9: acier type | I9: Sollicitation corde | J9: Alerte Sollicitation | K9: Variation de masse note | L9: coefficient d'inharmonicité B âme | M9: Inharmonicité âme octave, % 1/2 ton | N9: Inharmonicité âme octave % | O9: Tension corde en Newtons | P9: Tension note en Newtons | Q9: Sollicitation voulue | R9: Tension corde voulue | S9: Ø total (mm) | T9: Ø total arrondi | U9: Ø en place (mm) | V9: Ø avant déformation (mm) | W9: Alerte fil de trait trop fin | X9: Ø en place d1 (mm) | Y9: Ø d1 avant déformation (mm) | Z9: Ø d2 avant déformation (mm) | AC9: Fabricant corde acier | AD9: Fréquence parfaite (Hz) | AE9: F | AF9: 2 | AG9: 1 | AH9: fréquence aiguë modifié par inharmonicité | AI9: fréquence modifié par inharmonicité | AJ9: Diamètre total (mm) | AK9: Tension Statique corde en Newtons | AL9: Tension Statique note en Newtons | AM9: Sollicitation statique âme seule | AN9: Diamètre du fil de trait cuivre avant déformation (mm) | AO9: S min | AP9: S max | AQ9: Ctrl tension entre limites | AR9: index | AS9: cherche CR réelle | AT9: CRP réf | AU9: Tension dynamique corde filée | AV9: Diamètre fil de trait bi d1 avant déformation (mm) | AW9: diamètre corde pleine équivalente corde filée | AX9: tension statique voulue | AY9: diamètre acier idéal | AZ9: coef masseV | BA9: Var masseV % | BB9: Inharmonicité âme octave, Jean Louchet | BC9: H | BD9: Inharmonicité âme partiel H | BE9: Inharmonicité corde filée Fletcher | BF9: coefficient d'inharmonicité B | BG9: fréq longitudinale H1
A10: min graphiques | C10: limite | K10: -0.2 | O10: 0
A11: Max graphiques | C11: limite | K11: 0.8 | M11: 0.8 | O11: 1000
A13: =IF(ISBLANK(D13),"-",IF(AND($A$6,$A$4/2<AD13),AG13,AD13)) -> 27.5 | B13: =IF(ISBLANK(D13),"",VLOOKUP(MOD(C13-Paramètres!$B$54,12)+1,Paramètres!$B$40:$C$52,2)&" "&(TRUNC((C13-Paramètres!$B$54+120)/12)-10+1)) -> La -1 | C13: 1 | D13: 1177 | E13: 1 | F13: 6 | G13: 1 | H13: SP-M | I13: =IF(ISBLANK(D13),"",IF(F13>0,AU13/AT13,AM13)) -> 0.60714071 | J13: =IF(ISBLANK(D13),"",IF(AQ13,"","]"&AO13&" -- "&AP13&"[")) | L13: =IF(ISBLANK(D13),"",IF(F13>0,BF13,BF13)) -> 8.4451683e-05 | M13: =IF(ISBLANK(D13),"",IF(F13>0,"-",N13/(2^(1/12)-1))) -> - | N13: =IF(ISBLANK(D13),"",IF(F13>0,"-",1.5*L13)) -> - | O13: =IF(ISBLANK(D13),"",IF(F13>0,AU13,AK13)) -> 836.48812 | P13: =IF(ISBLANK(D13),"",IF(F13>0,AU13*G13,AL13)) -> 836.48812 | Q13: 0.6 | R13: =IF(ISBLANK(D13),"",AT13*Q13) -> 826.65 | S13: =IF(ISBLANK(D13),"",AJ13) -> 5.9644981 | T13: =IF(ISBLANK(F13),"",ROUND(S13*10*G13,0)/10/G13) -> 6 | U13: =IF(F13>0,(AJ13-E13)/2,"") -> 2.4822491 | V13: =IF(F13>0,AN13,"") -> 2.8410767 | W13: =IF(F13>0,IF(U13<Paramètres!$B$5,"!!!",""),"") | X13: =IF(U13<>"",IF(U13/3>=Paramètres!$B$5,(S13-E13)/2/3,""),"") -> 0.82741635 | Y13: =IF(U13<>"",IF(U13/3>=Paramètres!$B$5,AV13,""),"") -> 0.90850315 | Z13: =IF(X13<>"",Y13*2,"") -> 1.8170063 | AC13: =INDEX('Charge de rupture par diamètre'!$C$1:$AC$1,AR13) -> Stephen Paulello France | AD13: =IF(ISBLANK(D13),"-",$A$4/16 * 2^((C13-1)/12)) -> 27.5 | AE13: =AF13/(AF$9*SQRT(1+$L13*AF$9^2)) -> 82.425444 | AF13: =AG25 -> 164.87873 | AG13: =$AE13*AG$9*SQRT(1+$G13*AG$9^2) -> 116.56718 | AH13: =AD13 -> 27.5 | AI13: =IF(AND(C13>12,F1="",AD13>$A$4),AH1*2*(1+N1),IF(AD13>=$A$4/2,AD13,AH25/2/(1+N13))) -> #VALUE! | AJ13: =IF(Q13>0,((R13*10^12/PI()/A13^2/D13^2-Paramètres!$B$7*E13^2)*4/PI()/Paramètres!$B$8+E13^2)^0.5,"") -> 5.9644981 | AK13: =PI()*Paramètres!$B$7*(E13*A13*D13)^2/10^12 -> 25.836748 | AL13: =AK13*G13 -> 25.836748 | AM13: =AK13/AT13 -> 0.018752856 | AN13: =(-E13+0.1*Paramètres!$B$7/E13/Paramètres!$B$8/PI()*(AW13^2-E13^2)+(E13^2+3.8*Paramètres!$B$7/Paramètres!$B$8/PI()*(AW13^2-E13^2))^0.5)/2 -> 2.8410767 | AO13: =VLOOKUP(C13,Paramètres!$C$30:$F$37,2,1) -> 0.5 | AP13: =VLOOKUP(C13,Paramètres!$C$30:$F$37,4,1) -> 0.65 | AQ13: =AND(I13>=AO13,I13<=AP13) -> TRUE | AR13: =HLOOKUP(H13,'Charge de rupture par diamètre'!$D$16:$AC$17,2,0) -> 3 | AS13: =VLOOKUP(E13,'Charge de rupture par diamètre'!$C$16:$AC$53,AR13,1) -> 1837 | AT13: =AS13*Paramètres!$B$9 -> 1377.75 | AU13: =PI()*A13^2*D13^2*(Paramètres!$B$7*E13^2+Paramètres!$B$8*PI()/4*(F13^2-E13^2))/10^12 -> 836.48812 | AV13: =0.183*(-E13+(E13^2+4*Paramètres!$B$7/PI()/Paramètres!$B$8*(AW13^2-E13^2))^0.5) -> 0.90850315 | AW13: =(R13/PI()/Paramètres!$B$7)^0.5/A13/D13*10^6 -> 5.6564234 | AX13: =Q13*VLOOKUP(H13,Paramètres!$B$15:$C$18,2,0)*Paramètres!$B$9 -> #N/A | AY13: =(AX13/PI()/Paramètres!$B$7)^0.5/A13/D13*10^6 -> #N/A | AZ13: =(IF(F13>0,(F13*F13 -E13*E13)/Paramètres!$B$7*Paramètres!$B$8,0)+E13*E13)*D13*G13 -> 48197.025 | BB13: =IF(F13>0,"",0.234*Paramètres!$B$12*10^9*IF(F13>0,E13,E13)^2/Paramètres!$B$7/A13^2/D13^4*10^6) | BC13: 2 | BD13: =BC13*SQRT(1+L13*BC13^2)-BC13 -> 0.00033777821 | BE13: =IF(F13>0,PI()^2*Paramètres!$B$12*10^9/8/O13*(E13^4+E13^2*F13^2)*10^-12/D13^2/10^-6,"-") -> 0.0079570145 | BF13: =IF(ISBLANK(D13),"-",PI()^3*E13^4*Paramètres!$B$12*10^9/64/O13/(D13/1000)^2*10^-12) -> 8.4451683e-05 | BG13: =(Paramètres!$B$12*10^9)^0.5/Paramètres!$B$7/2/D13*1000 -> 24.322016
A14: =IF(ISBLANK(D14),"-",IF(AND($A$6,$A$4/2<AD14),AG14,AD14)) -> 29.135235 | B14: =IF(ISBLANK(D14),"",VLOOKUP(MOD(C14-Paramètres!$B$54,12)+1,Paramètres!$B$40:$C$52,2)&" "&(TRUNC((C14-Paramètres!$B$54+120)/12)-10+1)) -> La# -1 | C14: =IF(ISBLANK(D14),"",C13+1) -> 2 | D14: 1174 | E14: 1 | F14: 5.6 | G14: 1 | H14: SP-M | I14: =IF(ISBLANK(D14),"",IF(F14>0,AU14/AT14,AM14)) -> 0.59091268 | J14: =IF(ISBLANK(D14),"",IF(AQ14,"","]"&AO14&" -- "&AP14&"[")) | K14: =IF(ISBLANK(D14),"",BA14) -> -0.13155316 | L14: =IF(ISBLANK(D14),"",IF(F14>0,BF14,BF14)) -> 8.7214982e-05 | M14: =IF(ISBLANK(D14),"",IF(F14>0,"-",N14/(2^(1/12)-1))) -> - | N14: =IF(ISBLANK(D14),"",IF(F14>0,"-",1.5*L14)) -> - | O14: =IF(ISBLANK(D14),"",IF(F14>0,AU14,AK14)) -> 814.12994 | P14: =IF(ISBLANK(D14),"",IF(F14>0,AU14*G14,AL14)) -> 814.12994 | Q14: 0.6 | R14: =IF(ISBLANK(D14),"",AT14*Q14) -> 826.65 | S14: =IF(ISBLANK(D14),"",AJ14) -> 5.6430528 | T14: =IF(ISBLANK(F14),"",ROUND(S14*10*G14,0)/10/G14) -> 5.6 | U14: =IF(F14>0,(AJ14-E14)/2,"") -> 2.3215264 | V14: =IF(F14>0,AN14,"") -> 2.637906 | W14: =IF(F14>0,IF(U14<Paramètres!$B$5,"!!!",""),"") | X14: =IF(U14<>"",IF(U14/3>=Paramètres!$B$5,(S14-E14)/2/3,""),"") -> 0.77384213 | Y14: =IF(U14<>"",IF(U14/3>=Paramètres!$B$5,AV14,""),"") -> 0.84967866 | Z14: =IF(X14<>"",Y14*2,"") -> 1.6993573 | AC14: =INDEX('Charge de rupture par diamètre'!$C$1:$AC$1,AR14) -> Stephen Paulello France | AD14: =IF(ISBLANK(D14),"-",$A$4/16 * 2^((C14-1)/12)) -> 29.135235 | AE14: =AF14/(AF$9*SQRT(1+$L14*AF$9^2)) -> 87.327498 | AF14: =AG26 -> 174.68546 | AG14: =$AE14*AG$9*SQRT(1+$G14*AG$9^2) -> 123.49973 | AH14: =IF(AND(C14>12,F2="",AD14>$A$4),AH2*2*(1+N2),IF(AD14>=$A$4/2,AD14,AD14)) -> 29.135235 | AI14: =IF(AND(C14>12,F2="",AD14>$A$4),AH2*2*(1+N2),IF(AD14>=$A$4/2,AD14,AH26/2/(1+N14))) -> #VALUE! | AJ14: =IF(Q14>0,((R14*10^12/PI()/A14^2/D14^2-Paramètres!$B$7*E14^2)*4/PI()/Paramètres!$B$8+E14^2)^0.5,"") -> 5.6430528 | AK14: =PI()*Paramètres!$B$7*(E14*A14*D14)^2/10^12 -> 28.85312 | AL14: =AK14*G14 -> 28.85312 | AM14: =AK14/AT14 -> 0.020942203 | AN14: =(-E14+0.1*Paramètres!$B$7/E14/Paramètres!$B$8/PI()*(AW14^2-E14^2)+(E14^2+3.8*Paramètres!$B$7/Paramètres!$B$8/PI()*(AW14^2-E14^2))^0.5)/2 -> 2.637906 | AO14: =VLOOKUP(C14,Paramètres!$C$30:$F$37,2,1) -> 0.5 | AP14: =VLOOKUP(C14,Paramètres!$C$30:$F$37,4,1) -> 0.65 | AQ14: =AND(I14>=AO14,I14<=AP14) -> TRUE | AR14: =HLOOKUP(H14,'Charge de rupture par diamètre'!$D$16:$AC$17,2,0) -> 3 | AS14: =VLOOKUP(E14,'Charge de rupture par diamètre'!$C$16:$AC$53,AR14,1) -> 1837 | AT14: =AS14*Paramètres!$B$9 -> 1377.75 | AU14: =PI()*A14^2*D14^2*(Paramètres!$B$7*E14^2+Paramètres!$B$8*PI()/4*(F14^2-E14^2))/10^12 -> 814.12994 | AV14: =0.183*(-E14+(E14^2+4*Paramètres!$B$7/PI()/Paramètres!$B$8*(AW14^2-E14^2))^0.5) -> 0.84967866 | AW14: =(R14/PI()/Paramètres!$B$7)^0.5/A14/D14*10^6 -> 5.3525958 | AX14: =Q14*VLOOKUP(H14,Paramètres!$B$15:$C$18,2,0)*Paramètres!$B$9 -> #N/A | AY14: =(AX14/PI()/Paramètres!$B$7)^0.5/A14/D14*10^6 -> #N/A | AZ14: =(IF(F14>0,(F14*F14 -E14*E14)/Paramètres!$B$7*Paramètres!$B$8,0)+E14*E14)*D14*G14 -> 41856.555 | BA14: =-1+AZ14/AZ13 -> -0.13155316 | BB14: =IF(F14>0,"",0.234*Paramètres!$B$12*10^9*IF(F14>0,E14,E14)^2/Paramètres!$B$7/A14^2/D14^4*10^6) | BC14: 2 | BD14: =BC14*SQRT(1+L14*BC14^2)-BC14 -> 0.00034882951 | BE14: =IF(F14>0,PI()^2*Paramètres!$B$12*10^9/8/O14*(E14^4+E14^2*F14^2)*10^-12/D14^2/10^-6,"-") -> 0.0071868689 | BF14: =IF(ISBLANK(D14),"-",PI()^3*E14^4*Paramètres!$B$12*10^9/64/O14/(D14/1000)^2*10^-12) -> 8.7214982e-05 | BG14: =(Paramètres!$B$12*10^9)^0.5/Paramètres!$B$7/2/D14*1000 -> 24.384168
A15: =IF(ISBLANK(D15),"-",IF(AND($A$6,$A$4/2<AD15),AG15,AD15)) -> 30.867706 | B15: =IF(ISBLANK(D15),"",VLOOKUP(MOD(C15-Paramètres!$B$54,12)+1,Paramètres!$B$40:$C$52,2)&" "&(TRUNC((C15-Paramètres!$B$54+120)/12)-10+1)) -> Si -1 | C15: =IF(ISBLANK(D15),"",C14+1) -> 3 | D15: 1170 | E15: 1 | F15: 5.3 | G15: 1 | H15: SP-M | I15: =IF(ISBLANK(D15),"",IF(F15>0,AU15/AT15,AM15)) -> 0.59032568 | J15: =IF(ISBLANK(D15),"",IF(AQ15,"","]"&AO15&" -- "&AP15&"[")) | K15: =IF(ISBLANK(D15),"",BA15) -> -0.10773698 | L15: =IF(ISBLANK(D15),"",IF(F15>0,BF15,BF15)) -> 8.789966e-05 | M15: =IF(ISBLANK(D15),"",IF(F15>0,"-",N15/(2^(1/12)-1))) -> - | N15: =IF(ISBLANK(D15),"",IF(F15>0,"-",1.5*L15)) -> - | O15: =IF(ISBLANK(D15),"",IF(F15>0,AU15,AK15)) -> 813.32121 | P15: =IF(ISBLANK(D15),"",IF(F15>0,AU15*G15,AL15)) -> 813.32121 | Q15: 0.6 | R15: =IF(ISBLANK(D15),"",AT15*Q15) -> 826.65 | S15: =IF(ISBLANK(D15),"",AJ15) -> 5.3434291 | T15: =IF(ISBLANK(F15),"",ROUND(S15*10*G15,0)/10/G15) -> 5.3 | U15: =IF(F15>0,(AJ15-E15)/2,"") -> 2.1717146 | V15: =IF(F15>0,AN15,"") -> 2.4508672 | W15: =IF(F15>0,IF(U15<Paramètres!$B$5,"!!!",""),"") | X15: =IF(U15<>"",IF(U15/3>=Paramètres!$B$5,(S15-E15)/2/3,""),"") -> 0.72390485 | Y15: =IF(U15<>"",IF(U15/3>=Paramètres!$B$5,AV15,""),"") -> 0.79484753 | Z15: =IF(X15<>"",Y15*2,"") -> 1.5896951 | AC15: =INDEX('Charge de rupture par diamètre'!$C$1:$AC$1,AR15) -> Stephen Paulello France | AD15: =IF(ISBLANK(D15),"-",$A$4/16 * 2^((C15-1)/12)) -> 30.867706 | AE15: =AF15/(AF$9*SQRT(1+$L15*AF$9^2)) -> 92.520933 | AF15: =AG27 -> 185.07439 | AG15: =$AE15*AG$9*SQRT(1+$G15*AG$9^2) -> 130.84436 | AH15: =IF(AND(C15>12,F3="",AD15>$A$4),AH3*2*(1+N3),IF(AD15>=$A$4/2,AD15,AD15)) -> 30.867706 | AI15: =IF(AND(C15>12,F3="",AD15>$A$4),AH3*2*(1+N3),IF(AD15>=$A$4/2,AD15,AH27/2/(1+N15))) -> #VALUE! | AJ15: =IF(Q15>0,((R15*10^12/PI()/A15^2/D15^2-Paramètres!$B$7*E15^2)*4/PI()/Paramètres!$B$8+E15^2)^0.5,"") -> 5.3434291 | AK15: =PI()*Paramètres!$B$7*(E15*A15*D15)^2/10^12 -> 32.166216 | AL15: =AK15*G15 -> 32.166216 | AM15: =AK15/AT15 -> 0.023346918 | AN15: =(-E15+0.1*Paramètres!$B$7/E15/Paramètres!$B$8/PI()*(AW15^2-E15^2)+(E15^2+3.8*Paramètres!$B$7/Paramètres!$B$8/PI()*(AW15^2-E15^2))^0.5)/2 -> 2.4508672 | AO15: =VLOOKUP(C15,Paramètres!$C$30:$F$37,2,1) -> 0.5 | AP15: =VLOOKUP(C15,Paramètres!$C$30:$F$37,4,1) -> 0.65 | AQ15: =AND(I15>=AO15,I15<=AP15) -> TRUE | AR15: =HLOOKUP(H15,'Charge de rupture par diamètre'!$D$16:$AC$17,2,0) -> 3 | AS15: =VLOOKUP(E15,'Charge de rupture par diamètre'!$C$16:$AC$53,AR15,1) -> 1837 | AT15: =AS15*Paramètres!$B$9 -> 1377.75 | AU15: =PI()*A15^2*D15^2*(Paramètres!$B$7*E15^2+Paramètres!$B$8*PI()/4*(F15^2-E15^2))/10^12 -> 813.32121 | AV15: =0.183*(-E15+(E15^2+4*Paramètres!$B$7/PI()/Paramètres!$B$8*(AW15^2-E15^2))^0.5) -> 0.79484753 | AW15: =(R15/PI()/Paramètres!$B$7)^0.5/A15/D15*10^6 -> 5.0694501 | AX15: =Q15*VLOOKUP(H15,Paramètres!$B$15:$C$18,2,0)*Paramètres!$B$9 -> #N/A | AY15: =(AX15/PI()/Paramètres!$B$7)^0.5/A15/D15*10^6 -> #N/A | AZ15: =(IF(F15>0,(F15*F15 -E15*E15)/Paramètres!$B$7*Paramètres!$B$8,0)+E15*E15)*D15*G15 -> 37347.056 | BA15: =-1+AZ15/AZ14 -> -0.10773698 | BB15: =IF(F15>0,"",0.234*Paramètres!$B$12*10^9*IF(F15>0,E15,E15)^2/Paramètres!$B$7/A15^2/D15^4*10^6) | BC15: 2 | BD15: =BC15*SQRT(1+L15*BC15^2)-BC15 -> 0.00035156774 | BE15: =IF(F15>0,PI()^2*Paramètres!$B$12*10^9/8/O15*(E15^4+E15^2*F15^2)*10^-12/D15^2/10^-6,"-") -> 0.0065113498 | BF15: =IF(ISBLANK(D15),"-",PI()^3*E15^4*Paramètres!$B$12*10^9/64/O15/(D15/1000)^2*10^-12) -> 8.789966e-05 | BG15: =(Paramètres!$B$12*10^9)^0.5/Paramètres!$B$7/2/D15*1000 -> 24.467532
A16: =IF(ISBLANK(D16),"-",IF(AND($A$6,$A$4/2<AD16),AG16,AD16)) -> 32.703196 | B16: =IF(ISBLANK(D16),"",VLOOKUP(MOD(C16-Paramètres!$B$54,12)+1,Paramètres!$B$40:$C$52,2)&" "&(TRUNC((C16-Paramètres!$B$54+120)/12)-10+1)) -> Do 0 | C16: =IF(ISBLANK(D16),"",C15+1) -> 4 | D16: 1166 | E16: 1 | F16: 5.1 | G16: 1 | H16: SP-M | I16: =IF(ISBLANK(D16),"",IF(F16>0,AU16/AT16,AM16)) -> 0.60956432 | J16: =IF(ISBLANK(D16),"",IF(AQ16,"","]"&AO16&" -- "&AP16&"[")) | K16: =IF(ISBLANK(D16),"",BA16) -> -0.077540247 | L16: =IF(ISBLANK(D16),"",IF(F16>0,BF16,BF16)) -> 8.5710486e-05 | M16: =IF(ISBLANK(D16),"",IF(F16>0,"-",N16/(2^(1/12)-1))) -> - | N16: =IF(ISBLANK(D16),"",IF(F16>0,"-",1.5*L16)) -> - | O16: =IF(ISBLANK(D16),"",IF(F16>0,AU16,AK16)) -> 839.82724 | P16: =IF(ISBLANK(D16),"",IF(F16>0,AU16*G16,AL16)) -> 839.82724 | Q16: 0.6 | R16: =IF(ISBLANK(D16),"",AT16*Q16) -> 826.65 | S16: =IF(ISBLANK(D16),"",AJ16) -> 5.0596522 | T16: =IF(ISBLANK(F16),"",ROUND(S16*10*G16,0)/10/G16) -> 5.1 | U16: =IF(F16>0,(AJ16-E16)/2,"") -> 2.0298261 | V16: =IF(F16>0,AN16,"") -> 2.2758039 | W16: =IF(F16>0,IF(U16<Paramètres!$B$5,"!!!",""),"") | X16: =IF(U16<>"",IF(U16/3>=Paramètres!$B$5,(S16-E16)/2/3,""),"") -> 0.67660869 | Y16: =IF(U16<>"",IF(U16/3>=Paramètres!$B$5,AV16,""),"") -> 0.74291635 | Z16: =IF(X16<>"",Y16*2,"") -> 1.4858327 | AC16: =INDEX('Charge de rupture par diamètre'!$C$1:$AC$1,AR16) -> Stephen Paulello France | AD16: =IF(ISBLANK(D16),"-",$A$4/16 * 2^((C16-1)/12)) -> 32.703196 | AE16: =AF16/(AF$9*SQRT(1+$L16*AF$9^2)) -> 98.023481 | AF16: =AG28 -> 196.08057 | AG16: =$AE16*AG$9*SQRT(1+$G16*AG$9^2) -> 138.62614 | AH16: =IF(AND(C16>12,F4="",AD16>$A$4),AH4*2*(1+N4),IF(AD16>=$A$4/2,AD16,AD16)) -> 32.703196 | AI16: =IF(AND(C16>12,F4="",AD16>$A$4),AH4*2*(1+N4),IF(AD16>=$A$4/2,AD16,AH28/2/(1+N16))) -> #VALUE! | AJ16: =IF(Q16>0,((R16*10^12/PI()/A16^2/D16^2-Paramètres!$B$7*E16^2)*4/PI()/Paramètres!$B$8+E16^2)^0.5,"") -> 5.0596522 | AK16: =PI()*Paramètres!$B$7*(E16*A16*D16)^2/10^12 -> 35.858904 | AL16: =AK16*G16 -> 35.858904 | AM16: =AK16/AT16 -> 0.026027149 | AN16: =(-E16+0.1*Paramètres!$B$7/E16/Paramètres!$B$8/PI()*(AW16^2-E16^2)+(E16^2+3.8*Paramètres!$B$7/Paramètres!$B$8/PI()*(AW16^2-E16^2))^0.5)/2 -> 2.2758039 | AO16: =VLOOKUP(C16,Paramètres!$C$30:$F$37,2,1) -> 0.5 | AP16: =VLOOKUP(C16,Paramètres!$C$30:$F$37,4,1) -> 0.65 | AQ16: =AND(I16>=AO16,I16<=AP16) -> TRUE | AR16: =HLOOKUP(H16,'Charge de rupture par diamètre'!$D$16:$AC$17,2,0) -> 3 | AS16: =VLOOKUP(E16,'Charge de rupture par diamètre'!$C$16:$AC$53,AR16,1) -> 1837 | AT16: =AS16*Paramètres!$B$9 -> 1377.75 | AU16: =PI()*A16^2*D16^2*(Paramètres!$B$7*E16^2+Paramètres!$B$8*PI()/4*(F16^2-E16^2))/10^12 -> 839.82724 | AV16: =0.183*(-E16+(E16^2+4*Paramètres!$B$7/PI()/Paramètres!$B$8*(AW16^2-E16^2))^0.5) -> 0.74291635 | AW16: =(R16/PI()/Paramètres!$B$7)^0.5/A16/D16*10^6 -> 4.8013385 | AX16: =Q16*VLOOKUP(H16,Paramètres!$B$15:$C$18,2,0)*Paramètres!$B$9 -> #N/A | AY16: =(AX16/PI()/Paramètres!$B$7)^0.5/A16/D16*10^6 -> #N/A | AZ16: =(IF(F16>0,(F16*F16 -E16*E16)/Paramètres!$B$7*Paramètres!$B$8,0)+E16*E16)*D16*G16 -> 34451.156 | BA16: =-1+AZ16/AZ15 -> -0.077540247 | BB16: =IF(F16>0,"",0.234*Paramètres!$B$12*10^9*IF(F16>0,E16,E16)^2/Paramètres!$B$7/A16^2/D16^4*10^6) | BC16: 2 | BD16: =BC16*SQRT(1+L16*BC16^2)-BC16 -> 0.00034281256 | BE16: =IF(F16>0,PI()^2*Paramètres!$B$12*10^9/8/O16*(E16^4+E16^2*F16^2)*10^-12/D16^2/10^-6,"-") -> 0.0058952015 | BF16: =IF(ISBLANK(D16),"-",PI()^3*E16^4*Paramètres!$B$12*10^9/64/O16/(D16/1000)^2*10^-12) -> 8.5710486e-05 | BG16: =(Paramètres!$B$12*10^9)^0.5/Paramètres!$B$7/2/D16*1000 -> 24.551469
A17: =IF(ISBLANK(D17),"-",IF(AND($A$6,$A$4/2<AD17),AG17,AD17)) -> 34.647829 | B17: =IF(ISBLANK(D17),"",VLOOKUP(MOD(C17-Paramètres!$B$54,12)+1,Paramètres!$B$40:$C$52,2)&" "&(TRUNC((C17-Paramètres!$B$54+120)/12)-10+1)) -> Do# 0 | C17: =IF(ISBLANK(D17),"",C16+1) -> 5 | D17: 1161 | E17: 1 | F17: 4.8 | G17: 1 | H17: SP-M | I17: =IF(ISBLANK(D17),"",IF(F17>0,AU17/AT17,AM17)) -> 0.60124033 | J17: =IF(ISBLANK(D17),"",IF(AQ17,"","]"&AO17&" -- "&AP17&"[")) | K17: =IF(ISBLANK(D17),"",BA17) -> -0.11852949 | L17: =IF(ISBLANK(D17),"",IF(F17>0,BF17,BF17)) -> 8.7647201e-05 | M17: =IF(ISBLANK(D17),"",IF(F17>0,"-",N17/(2^(1/12)-1))) -> - | N17: =IF(ISBLANK(D17),"",IF(F17>0,"-",1.5*L17)) -> - | O17: =IF(ISBLANK(D17),"",IF(F17>0,AU17,AK17)) -> 828.35886 | P17: =IF(ISBLANK(D17),"",IF(F17>0,AU17*G17,AL17)) -> 828.35886 | Q17: 0.6 | R17: =IF(ISBLANK(D17),"",AT17*Q17) -> 826.65 | S17: =IF(ISBLANK(D17),"",AJ17) -> 4.7950215 | T17: =IF(ISBLANK(F17),"",ROUND(S17*10*G17,0)/10/G17) -> 4.8 | U17: =IF(F17>0,(AJ17-E17)/2,"") -> 1.8975108 | V17: =IF(F17>0,AN17,"") -> 2.1143804 | W17: =IF(F17>0,IF(U17<Paramètres!$B$5,"!!!",""),"") | X17: =IF(U17<>"",IF(U17/3>=Paramètres!$B$5,(S17-E17)/2/3,""),"") -> 0.63250359 | Y17: =IF(U17<>"",IF(U17/3>=Paramètres!$B$5,AV17,""),"") -> 0.69448894 | Z17: =IF(X17<>"",Y17*2,"") -> 1.3889779 | AC17: =INDEX('Charge de rupture par diamètre'!$C$1:$AC$1,AR17) -> Stephen Paulello France | AD17: =IF(ISBLANK(D17),"-",$A$4/16 * 2^((C17-1)/12)) -> 34.647829 | AE17: =AF17/(AF$9*SQRT(1+$L17*AF$9^2)) -> 119.89256 | AF17: =AG29 -> 239.82715 | AG17: =$AE17*AG$9*SQRT(1+$G17*AG$9^2) -> 169.55369 | AH17: =IF(AND(C17>12,F5="",AD17>$A$4),AH5*2*(1+N5),IF(AD17>=$A$4/2,AD17,AD17)) -> 34.647829 | AI17: =IF(AND(C17>12,F5="",AD17>$A$4),AH5*2*(1+N5),IF(AD17>=$A$4/2,AD17,AH29/2/(1+N17))) -> #VALUE! | AJ17: =IF(Q17>0,((R17*10^12/PI()/A17^2/D17^2-Paramètres!$B$7*E17^2)*4/PI()/Paramètres!$B$8+E17^2)^0.5,"") -> 4.7950215 | AK17: =PI()*Paramètres!$B$7*(E17*A17*D17)^2/10^12 -> 39.9058 | AL17: =AK17*G17 -> 39.9058 | AM17: =AK17/AT17 -> 0.028964471 | AN17: =(-E17+0.1*Paramètres!$B$7/E17/Paramètres!$B$8/PI()*(AW17^2-E17^2)+(E17^2+3.8*Paramètres!$B$7/Paramètres!$B$8/PI()*(AW17^2-E17^2))^0.5)/2 -> 2.1143804 | AO17: =VLOOKUP(C17,Paramètres!$C$30:$F$37,2,1) -> 0.5 | AP17: =VLOOKUP(C17,Paramètres!$C$30:$F$37,4,1) -> 0.65 | AQ17: =AND(I17>=AO17,I17<=AP17) -> TRUE | AR17: =HLOOKUP(H17,'Charge de rupture par diamètre'!$D$16:$AC$17,2,0) -> 3 | AS17: =VLOOKUP(E17,'Charge de rupture par diamètre'!$C$16:$AC$53,AR17,1) -> 1837 | AT17: =AS17*Paramètres!$B$9 -> 1377.75 | AU17: =PI()*A17^2*D17^2*(Paramètres!$B$7*E17^2+Paramètres!$B$8*PI()/4*(F17^2-E17^2))/10^12 -> 828.35886 | AV17: =0.183*(-E17+(E17^2+4*Paramètres!$B$7/PI()/Paramètres!$B$8*(AW17^2-E17^2))^0.5) -> 0.69448894 | AW17: =(R17/PI()/Paramètres!$B$7)^0.5/A17/D17*10^6 -> 4.5513772 | AX17: =Q17*VLOOKUP(H17,Paramètres!$B$15:$C$18,2,0)*Paramètres!$B$9 -> #N/A | AY17: =(AX17/PI()/Paramètres!$B$7)^0.5/A17/D17*10^6 -> #N/A | AZ17: =(IF(F17>0,(F17*F17 -E17*E17)/Paramètres!$B$7*Paramètres!$B$8,0)+E17*E17)*D17*G17 -> 30367.678 | BA17: =-1+AZ17/AZ16 -> -0.11852949 | BB17: =IF(F17>0,"",0.234*Paramètres!$B$12*10^9*IF(F17>0,E17,E17)^2/Paramètres!$B$7/A17^2/D17^4*10^6) | BC17: 2 | BD17: =BC17*SQRT(1+L17*BC17^2)-BC17 -> 0.00035055808 | BE17: =IF(F17>0,PI()^2*Paramètres!$B$12*10^9/8/O17*(E17^4+E17^2*F17^2)*10^-12/D17^2/10^-6,"-") -> 0.00536553 | BF17: =IF(ISBLANK(D17),"-",PI()^3*E17^4*Paramètres!$B$12*10^9/64/O17/(D17/1000)^2*10^-12) -> 8.7647201e-05 | BG17: =(Paramètres!$B$12*10^9)^0.5/Paramètres!$B$7/2/D17*1000 -> 24.657203
A18: =IF(ISBLANK(D18),"-",IF(AND($A$6,$A$4/2<AD18),AG18,AD18)) -> 36.708096 | B18: =IF(ISBLANK(D18),"",VLOOKUP(MOD(C18-Paramètres!$B$54,12)+1,Paramètres!$B$40:$C$52,2)&" "&(TRUNC((C18-Paramètres!$B$54+120)/12)-10+1)) -> Ré 0 | C18: =IF(ISBLANK(D18),"",C17+1) -> 6 | D18: 1156 | E18: 1 | F18: 4.5 | G18: 1 | H18: SP-M | I18: =IF(ISBLANK(D18),"",IF(F18>0,AU18/AT18,AM18)) -> 0.5884532 | J18: =IF(ISBLANK(D18),"",IF(AQ18,"","]"&AO18&" -- "&AP18&"[")) | K18: =IF(ISBLANK(D18),"",BA18) -> -0.12553069 | L18: =IF(ISBLANK(D18),"",IF(F18>0,BF18,BF18)) -> 9.0328126e-05 | M18: =IF(ISBLANK(D18),"",IF(F18>0,"-",N18/(2^(1/12)-1))) -> - | N18: =IF(ISBLANK(D18),"",IF(F18>0,"-",1.5*L18)) -> - | O18: =IF(ISBLANK(D18),"",IF(F18>0,AU18,AK18)) -> 810.74139 | P18: =IF(ISBLANK(D18),"",IF(F18>0,AU18*G18,AL18)) -> 810.74139 | Q18: 0.6 | R18: =IF(ISBLANK(D18),"",AT18*Q18) -> 826.65 | S18: =IF(ISBLANK(D18),"",AJ18) -> 4.5441851 | T18: =IF(ISBLANK(F18),"",ROUND(S18*10*G18,0)/10/G18) -> 4.5 | U18: =IF(F18>0,(AJ18-E18)/2,"") -> 1.7720925 | V18: =IF(F18>0,AN18,"") -> 1.9630025 | W18: =IF(F18>0,IF(U18<Paramètres!$B$5,"!!!",""),"") | X18: =IF(U18<>"",IF(U18/3>=Paramètres!$B$5,(S18-E18)/2/3,""),"") -> 0.59069751 | Y18: =IF(U18<>"",IF(U18/3>=Paramètres!$B$5,AV18,""),"") -> 0.64858587 | Z18: =IF(X18<>"",Y18*2,"") -> 1.2971717 | AC18: =INDEX('Charge de rupture par diamètre'!$C$1:$AC$1,AR18) -> Stephen Paulello France | AD18: =IF(ISBLANK(D18),"-",$A$4/16 * 2^((C18-1)/12)) -> 36.708096 | AE18: =AF18/(AF$9*SQRT(1+$L18*AF$9^2)) -> 127.02588 | AF18: =AG30 -> 254.09765 | AG18: =$AE18*AG$9*SQRT(1+$G18*AG$9^2) -> 179.64172 | AH18: =IF(AND(C18>12,F6="",AD18>$A$4),AH6*2*(1+N6),IF(AD18>=$A$4/2,AD18,AD18)) -> 36.708096 | AI18: =IF(AND(C18>12,F6="",AD18>$A$4),AH6*2*(1+N6),IF(AD18>=$A$4/2,AD18,AH30/2/(1+N18))) -> #VALUE! | AJ18: =IF(Q18>0,((R18*10^12/PI()/A18^2/D18^2-Paramètres!$B$7*E18^2)*4/PI()/Paramètres!$B$8+E18^2)^0.5,"") -> 4.5441851 | AK18: =PI()*Paramètres!$B$7*(E18*A18*D18)^2/10^12 -> 44.407765 | AL18: =AK18*G18 -> 44.407765 | AM18: =AK18/AT18 -> 0.032232092 | AN18: =(-E18+0.1*Paramètres!$B$7/E18/Paramètres!$B$8/PI()*(AW18^2-E18^2)+(E18^2+3.8*Paramètres!$B$7/Paramètres!$B$8/PI()*(AW18^2-E18^2))^0.5)/2 -> 1.9630025 | AO18: =VLOOKUP(C18,Paramètres!$C$30:$F$37,2,1) -> 0.5 | AP18: =VLOOKUP(C18,Paramètres!$C$30:$F$37,4,1) -> 0.65 | AQ18: =AND(I18>=AO18,I18<=AP18) -> TRUE | AR18: =HLOOKUP(H18,'Charge de rupture par diamètre'!$D$16:$AC$17,2,0) -> 3 | AS18: =VLOOKUP(E18,'Charge de rupture par diamètre'!$C$16:$AC$53,AR18,1) -> 1837 | AT18: =AS18*Paramètres!$B$9 -> 1377.75 | AU18: =PI()*A18^2*D18^2*(Paramètres!$B$7*E18^2+Paramètres!$B$8*PI()/4*(F18^2-E18^2))/10^12 -> 810.74139 | AV18: =0.183*(-E18+(E18^2+4*Paramètres!$B$7/PI()/Paramètres!$B$8*(AW18^2-E18^2))^0.5) -> 0.64858587 | AW18: =(R18/PI()/Paramètres!$B$7)^0.5/A18/D18*10^6 -> 4.314509 | AX18: =Q18*VLOOKUP(H18,Paramètres!$B$15:$C$18,2,0)*Paramètres!$B$9 -> #N/A | AY18: =(AX18/PI()/Paramètres!$B$7)^0.5/A18/D18*10^6 -> #N/A | AZ18: =(IF(F18>0,(F18*F18 -E18*E18)/Paramètres!$B$7*Paramètres!$B$8,0)+E18*E18)*D18*G18 -> 26555.603 | BA18: =-1+AZ18/AZ17 -> -0.12553069 | BB18: =IF(F18>0,"",0.234*Paramètres!$B$12*10^9*IF(F18>0,E18,E18)^2/Paramètres!$B$7/A18^2/D18^4*10^6) | BC18: 2 | BD18: =BC18*SQRT(1+L18*BC18^2)-BC18 -> 0.00036127987 | BE18: =IF(F18>0,PI()^2*Paramètres!$B$12*10^9/8/O18*(E18^4+E18^2*F18^2)*10^-12/D18^2/10^-6,"-") -> 0.004887897 | BF18: =IF(ISBLANK(D18),"-",PI()^3*E18^4*Paramètres!$B$12*10^9/64/O18/(D18/1000)^2*10^-12) -> 9.0328126e-05 | BG18: =(Paramètres!$B$12*10^9)^0.5/Paramètres!$B$7/2/D18*1000 -> 24.763852
A19: =IF(ISBLANK(D19),"-",IF(AND($A$6,$A$4/2<AD19),AG19,AD19)) -> 38.890873 | B19: =IF(ISBLANK(D19),"",VLOOKUP(MOD(C19-Paramètres!$B$54,12)+1,Paramètres!$B$40:$C$52,2)&" "&(TRUNC((C19-Paramètres!$B$54+120)/12)-10+1)) -> Ré# 0 | C19: =IF(ISBLANK(D19),"",C18+1) -> 7 | D19: 1151 | E19: 1 | F19: 4.3 | G19: 1 | H19: SP-M | I19: =IF(ISBLANK(D19),"",IF(F19>0,AU19/AT19,AM19)) -> 0.5982254 | J19: =IF(ISBLANK(D19),"",IF(AQ19,"","]"&AO19&" -- "&AP19&"[")) | K19: =IF(ISBLANK(D19),"",BA19) -> -0.091395588 | L19: =IF(ISBLANK(D19),"",IF(F19>0,BF19,BF19)) -> 8.9626223e-05 | M19: =IF(ISBLANK(D19),"",IF(F19>0,"-",N19/(2^(1/12)-1))) -> - | N19: =IF(ISBLANK(D19),"",IF(F19>0,"-",1.5*L19)) -> - | O19: =IF(ISBLANK(D19),"",IF(F19>0,AU19,AK19)) -> 824.20505 | P19: =IF(ISBLANK(D19),"",IF(F19>0,AU19*G19,AL19)) -> 824.20505 | Q19: 0.6 | R19: =IF(ISBLANK(D19),"",AT19*Q19) -> 826.65 | S19: =IF(ISBLANK(D19),"",AJ19) -> 4.3064129 | T19: =IF(ISBLANK(F19),"",ROUND(S19*10*G19,0)/10/G19) -> 4.3 | U19: =IF(F19>0,(AJ19-E19)/2,"") -> 1.6532064 | V19: =IF(F19>0,AN19,"") -> 1.8209769 | W19: =IF(F19>0,IF(U19<Paramètres!$B$5,"!!!",""),"") | X19: =IF(U19<>"",IF(U19/3>=Paramètres!$B$5,(S19-E19)/2/3,""),"") -> 0.55106882 | Y19: =IF(U19<>"",IF(U19/3>=Paramètres!$B$5,AV19,""),"") -> 0.60507356 | Z19: =IF(X19<>"",Y19*2,"") -> 1.2101471 | AC19: =INDEX('Charge de rupture par diamètre'!$C$1:$AC$1,AR19) -> Stephen Paulello France | AD19: =IF(ISBLANK(D19),"-",$A$4/16 * 2^((C19-1)/12)) -> 38.890873 | AE19: =AF19/(AF$9*SQRT(1+$L19*AF$9^2)) -> 134.58954 | AF19: =AG31 -> 269.22732 | AG19: =$AE19*AG$9*SQRT(1+$G19*AG$9^2) -> 190.33835 | AH19: =IF(AND(C19>12,F7="",AD19>$A$4),AH7*2*(1+N7),IF(AD19>=$A$4/2,AD19,AD19)) -> 38.890873 | AI19: =IF(AND(C19>12,F7="",AD19>$A$4),AH7*2*(1+N7),IF(AD19>=$A$4/2,AD19,AH31/2/(1+N19))) -> #VALUE! | AJ19: =IF(Q19>0,((R19*10^12/PI()/A19^2/D19^2-Paramètres!$B$7*E19^2)*4/PI()/Paramètres!$B$8+E19^2)^0.5,"") -> 4.3064129 | AK19: =PI()*Paramètres!$B$7*(E19*A19*D19)^2/10^12 -> 49.415769 | AL19: =AK19*G19 -> 49.415769 | AM19: =AK19/AT19 -> 0.035867007 | AN19: =(-E19+0.1*Paramètres!$B$7/E19/Paramètres!$B$8/PI()*(AW19^2-E19^2)+(E19^2+3.8*Paramètres!$B$7/Paramètres!$B$8/PI()*(AW19^2-E19^2))^0.5)/2 -> 1.8209769 | AO19: =VLOOKUP(C19,Paramètres!$C$30:$F$37,2,1) -> 0.5 | AP19: =VLOOKUP(C19,Paramètres!$C$30:$F$37,4,1) -> 0.65 | AQ19: =AND(I19>=AO19,I19<=AP19) -> TRUE | AR19: =HLOOKUP(H19,'Charge de rupture par diamètre'!$D$16:$AC$17,2,0) -> 3 | AS19: =VLOOKUP(E19,'Charge de rupture par diamètre'!$C$16:$AC$53,AR19,1) -> 1837 | AT19: =AS19*Paramètres!$B$9 -> 1377.75 | AU19: =PI()*A19^2*D19^2*(Paramètres!$B$7*E19^2+Paramètres!$B$8*PI()/4*(F19^2-E19^2))/10^12 -> 824.20505 | AV19: =0.183*(-E19+(E19^2+4*Paramètres!$B$7/PI()/Paramètres!$B$8*(AW19^2-E19^2))^0.5) -> 0.60507356 | AW19: =(R19/PI()/Paramètres!$B$7)^0.5/A19/D19*10^6 -> 4.0900447 | AX19: =Q19*VLOOKUP(H19,Paramètres!$B$15:$C$18,2,0)*Paramètres!$B$9 -> #N/A | AY19: =(AX19/PI()/Paramètres!$B$7)^0.5/A19/D19*10^6 -> #N/A | AZ19: =(IF(F19>0,(F19*F19 -E19*E19)/Paramètres!$B$7*Paramètres!$B$8,0)+E19*E19)*D19*G19 -> 24128.538 | BA19: =-1+AZ19/AZ18 -> -0.091395588 | BB19: =IF(F19>0,"",0.234*Paramètres!$B$12*10^9*IF(F19>0,E19,E19)^2/Paramètres!$B$7/A19^2/D19^4*10^6) | BC19: 2 | BD19: =BC19*SQRT(1+L19*BC19^2)-BC19 -> 0.00035847277 | BE19: =IF(F19>0,PI()^2*Paramètres!$B$12*10^9/8/O19*(E19^4+E19^2*F19^2)*10^-12/D19^2/10^-6,"-") -> 0.0044482281 | BF19: =IF(ISBLANK(D19),"-",PI()^3*E19^4*Paramètres!$B$12*10^9/64/O19/(D19/1000)^2*10^-12) -> 8.9626223e-05 | BG19: =(Paramètres!$B$12*10^9)^0.5/Paramètres!$B$7/2/D19*1000 -> 24.871427
A20: =IF(ISBLANK(D20),"-",IF(AND($A$6,$A$4/2<AD20),AG20,AD20)) -> 41.203445 | B20: =IF(ISBLANK(D20),"",VLOOKUP(MOD(C20-Paramètres!$B$54,12)+1,Paramètres!$B$40:$C$52,2)&" "&(TRUNC((C20-Paramètres!$B$54+120)/12)-10+1)) -> Mi 0 | C20: =IF(ISBLANK(D20),"",C19+1) -> 8 | D20: 1145 | E20: 1 | F20: 4.1 | G20: 1 | H20: SP-M | I20: =IF(ISBLANK(D20),"",IF(F20>0,AU20/AT20,AM20)) -> 0.60450099 | J20: =IF(ISBLANK(D20),"",IF(AQ20,"","]"&AO20&" -- "&AP20&"[")) | K20: =IF(ISBLANK(D20),"",BA20) -> -0.09620882 | L20: =IF(ISBLANK(D20),"",IF(F20>0,BF20,BF20)) -> 8.9627772e-05 | M20: =IF(ISBLANK(D20),"",IF(F20>0,"-",N20/(2^(1/12)-1))) -> - | N20: =IF(ISBLANK(D20),"",IF(F20>0,"-",1.5*L20)) -> - | O20: =IF(ISBLANK(D20),"",IF(F20>0,AU20,AK20)) -> 832.85124 | P20: =IF(ISBLANK(D20),"",IF(F20>0,AU20*G20,AL20)) -> 832.85124 | Q20: 0.6 | R20: =IF(ISBLANK(D20),"",AT20*Q20) -> 826.65 | S20: =IF(ISBLANK(D20),"",AJ20) -> 4.0846023 | T20: =IF(ISBLANK(F20),"",ROUND(S20*10*G20,0)/10/G20) -> 4.1 | U20: =IF(F20>0,(AJ20-E20)/2,"") -> 1.5423012 | V20: =IF(F20>0,AN20,"") -> 1.6897759 | W20: =IF(F20>0,IF(U20<Paramètres!$B$5,"!!!",""),"") | X20: =IF(U20<>"",IF(U20/3>=Paramètres!$B$5,(S20-E20)/2/3,""),"") -> 0.51410039 | Y20: =IF(U20<>"",IF(U20/3>=Paramètres!$B$5,AV20,""),"") -> 0.56448222 | Z20: =IF(X20<>"",Y20*2,"") -> 1.1289644 | AC20: =INDEX('Charge de rupture par diamètre'!$C$1:$AC$1,AR20) -> Stephen Paulello France | AD20: =IF(ISBLANK(D20),"-",$A$4/16 * 2^((C20-1)/12)) -> 41.203445 | AE20: =AF20/(AF$9*SQRT(1+$L20*AF$9^2)) -> 142.59644 | AF20: =AG32 -> 285.244 | AG20: =$AE20*AG$9*SQRT(1+$G20*AG$9^2) -> 201.66182 | AH20: =IF(AND(C20>12,F8="",AD20>$A$4),AH8*2*(1+N8),IF(AD20>=$A$4/2,AD20,AD20)) -> 41.203445 | AI20: =IF(AND(C20>12,F8="",AD20>$A$4),AH8*2*(1+N8),IF(AD20>=$A$4/2,AD20,AH32/2/(1+N20))) -> #VALUE! | AJ20: =IF(Q20>0,((R20*10^12/PI()/A20^2/D20^2-Paramètres!$B$7*E20^2)*4/PI()/Paramètres!$B$8+E20^2)^0.5,"") -> 4.0846023 | AK20: =PI()*Paramètres!$B$7*(E20*A20*D20)^2/10^12 -> 54.890546 | AL20: =AK20*G20 -> 54.890546 | AM20: =AK20/AT20 -> 0.039840716 | AN20: =(-E20+0.1*Paramètres!$B$7/E20/Paramètres!$B$8/PI()*(AW20^2-E20^2)+(E20^2+3.8*Paramètres!$B$7/Paramètres!$B$8/PI()*(AW20^2-E20^2))^0.5)/2 -> 1.6897759 | AO20: =VLOOKUP(C20,Paramètres!$C$30:$F$37,2,1) -> 0.5 | AP20: =VLOOKUP(C20,Paramètres!$C$30:$F$37,4,1) -> 0.65 | AQ20: =AND(I20>=AO20,I20<=AP20) -> TRUE | AR20: =HLOOKUP(H20,'Charge de rupture par diamètre'!$D$16:$AC$17,2,0) -> 3 | AS20: =VLOOKUP(E20,'Charge de rupture par diamètre'!$C$16:$AC$53,AR20,1) -> 1837 | AT20: =AS20*Paramètres!$B$9 -> 1377.75 | AU20: =PI()*A20^2*D20^2*(Paramètres!$B$7*E20^2+Paramètres!$B$8*PI()/4*(F20^2-E20^2))/10^12 -> 832.85124 | AV20: =0.183*(-E20+(E20^2+4*Paramètres!$B$7/PI()/Paramètres!$B$8*(AW20^2-E20^2))^0.5) -> 0.56448222 | AW20: =(R20/PI()/Paramètres!$B$7)^0.5/A20/D20*10^6 -> 3.8807178 | AX20: =Q20*VLOOKUP(H20,Paramètres!$B$15:$C$18,2,0)*Paramètres!$B$9 -> #N/A | AY20: =(AX20/PI()/Paramètres!$B$7)^0.5/A20/D20*10^6 -> #N/A | AZ20: =(IF(F20>0,(F20*F20 -E20*E20)/Paramètres!$B$7*Paramètres!$B$8,0)+E20*E20)*D20*G20 -> 21807.159 | BA20: =-1+AZ20/AZ19 -> -0.09620882 | BB20: =IF(F20>0,"",0.234*Paramètres!$B$12*10^9*IF(F20>0,E20,E20)^2/Paramètres!$B$7/A20^2/D20^4*10^6) | BC20: 2 | BD20: =BC20*SQRT(1+L20*BC20^2)-BC20 -> 0.00035847896 | BE20: =IF(F20>0,PI()^2*Paramètres!$B$12*10^9/8/O20*(E20^4+E20^2*F20^2)*10^-12/D20^2/10^-6,"-") -> 0.0040648698 | BF20: =IF(ISBLANK(D20),"-",PI()^3*E20^4*Paramètres!$B$12*10^9/64/O20/(D20/1000)^2*10^-12) -> 8.9627772e-05 | BG20: =(Paramètres!$B$12*10^9)^0.5/Paramètres!$B$7/2/D20*1000 -> 25.001758
A21: =IF(ISBLANK(D21),"-",IF(AND($A$6,$A$4/2<AD21),AG21,AD21)) -> 43.653529 | B21: =IF(ISBLANK(D21),"",VLOOKUP(MOD(C21-Paramètres!$B$54,12)+1,Paramètres!$B$40:$C$52,2)&" "&(TRUNC((C21-Paramètres!$B$54+120)/12)-10+1)) -> Fa 0 | C21: =IF(ISBLANK(D21),"",C20+1) -> 9 | D21: 1140 | E21: 1 | F21: 3.85 | G21: 2 | H21: SP-M | I21: =IF(ISBLANK(D21),"",IF(F21>0,AU21/AT21,AM21)) -> 0.59363347 | J21: =IF(ISBLANK(D21),"",IF(AQ21,"","]"&AO21&" -- "&AP21&"[")) | K21: =IF(ISBLANK(D21),"",BA21) -> 0.75408464 | L21: =IF(ISBLANK(D21),"",IF(F21>0,BF21,BF21)) -> 9.2070926e-05 | M21: =IF(ISBLANK(D21),"",IF(F21>0,"-",N21/(2^(1/12)-1))) -> - | N21: =IF(ISBLANK(D21),"",IF(F21>0,"-",1.5*L21)) -> - | O21: =IF(ISBLANK(D21),"",IF(F21>0,AU21,AK21)) -> 817.87852 | P21: =IF(ISBLANK(D21),"",IF(F21>0,AU21*G21,AL21)) -> 1635.757 | Q21: 0.6 | R21: =IF(ISBLANK(D21),"",AT21*Q21) -> 826.65 | S21: =IF(ISBLANK(D21),"",AJ21) -> 3.87075 | T21: =IF(ISBLANK(F21),"",ROUND(S21*10*G21,0)/10/G21) -> 3.85 | U21: =IF(F21>0,(AJ21-E21)/2,"") -> 1.435375 | V21: =IF(F21>0,AN21,"") -> 1.5644643 | W21: =IF(F21>0,IF(U21<Paramètres!$B$5,"!!!",""),"") | X21: =IF(U21<>"",IF(U21/3>=Paramètres!$B$5,(S21-E21)/2/3,""),"") -> 0.47845833 | Y21: =IF(U21<>"",IF(U21/3>=Paramètres!$B$5,AV21,""),"") -> 0.52534724 | Z21: =IF(X21<>"",Y21*2,"") -> 1.0506945 | AC21: =INDEX('Charge de rupture par diamètre'!$C$1:$AC$1,AR21) -> Stephen Paulello France | AD21: =IF(ISBLANK(D21),"-",$A$4/16 * 2^((C21-1)/12)) -> 43.653529 | AE21: =AF21/(AF$9*SQRT(1+$L21*AF$9^2)) -> 151.084 | AF21: =AG33 -> 302.22363 | AG21: =$AE21*AG$9*SQRT(1+$G21*AG$9^2) -> 261.68516 | AH21: =IF(AND(C21>12,F9="",AD21>$A$4),AH9*2*(1+N9),IF(AD21>=$A$4/2,AD21,AD21)) -> 43.653529 | AI21: =IF(AND(C21>12,F9="",AD21>$A$4),AH9*2*(1+N9),IF(AD21>=$A$4/2,AD21,AH33/2/(1+N21))) -> #VALUE! | AJ21: =IF(Q21>0,((R21*10^12/PI()/A21^2/D21^2-Paramètres!$B$7*E21^2)*4/PI()/Paramètres!$B$8+E21^2)^0.5,"") -> 3.87075 | AK21: =PI()*Paramètres!$B$7*(E21*A21*D21)^2/10^12 -> 61.075629 | AL21: =AK21*G21 -> 122.15126 | AM21: =AK21/AT21 -> 0.044329979 | AN21: =(-E21+0.1*Paramètres!$B$7/E21/Paramètres!$B$8/PI()*(AW21^2-E21^2)+(E21^2+3.8*Paramètres!$B$7/Paramètres!$B$8/PI()*(AW21^2-E21^2))^0.5)/2 -> 1.5644643 | AO21: =VLOOKUP(C21,Paramètres!$C$30:$F$37,2,1) -> 0.5 | AP21: =VLOOKUP(C21,Paramètres!$C$30:$F$37,4,1) -> 0.65 | AQ21: =AND(I21>=AO21,I21<=AP21) -> TRUE | AR21: =HLOOKUP(H21,'Charge de rupture par diamètre'!$D$16:$AC$17,2,0) -> 3 | AS21: =VLOOKUP(E21,'Charge de rupture par diamètre'!$C$16:$AC$53,AR21,1) -> 1837 | AT21: =AS21*Paramètres!$B$9 -> 1377.75 | AU21: =PI()*A21^2*D21^2*(Paramètres!$B$7*E21^2+Paramètres!$B$8*PI()/4*(F21^2-E21^2))/10^12 -> 817.87852 | AV21: =0.183*(-E21+(E21^2+4*Paramètres!$B$7/PI()/Paramètres!$B$8*(AW21^2-E21^2))^0.5) -> 0.52534724 | AW21: =(R21/PI()/Paramètres!$B$7)^0.5/A21/D21*10^6 -> 3.6789752 | AX21: =Q21*VLOOKUP(H21,Paramètres!$B$15:$C$18,2,0)*Paramètres!$B$9 -> #N/A | AY21: =(AX21/PI()/Paramètres!$B$7)^0.5/A21/D21*10^6 -> #N/A | AZ21: =(IF(F21>0,(F21*F21 -E21*E21)/Paramètres!$B$7*Paramètres!$B$8,0)+E21*E21)*D21*G21 -> 38251.604 | BA21: =-1+AZ21/AZ20 -> 0.75408464 | BB21: =IF(F21>0,"",0.234*Paramètres!$B$12*10^9*IF(F21>0,E21,E21)^2/Paramètres!$B$7/A21^2/D21^4*10^6) | BC21: 2 | BD21: =BC21*SQRT(1+L21*BC21^2)-BC21 -> 0.0003682498 | BE21: =IF(F21>0,PI()^2*Paramètres!$B$12*10^9/8/O21*(E21^4+E21^2*F21^2)*10^-12/D21^2/10^-6,"-") -> 0.0037096909 | BF21: =IF(ISBLANK(D21),"-",PI()^3*E21^4*Paramètres!$B$12*10^9/64/O21/(D21/1000)^2*10^-12) -> 9.2070926e-05 | BG21: =(Paramètres!$B$12*10^9)^0.5/Paramètres!$B$7/2/D21*1000 -> 25.111415
A22: =IF(ISBLANK(D22),"-",IF(AND($A$6,$A$4/2<AD22),AG22,AD22)) -> 46.249303 | B22: =IF(ISBLANK(D22),"",VLOOKUP(MOD(C22-Paramètres!$B$54,12)+1,Paramètres!$B$40:$C$52,2)&" "&(TRUNC((C22-Paramètres!$B$54+120)/12)-10+1)) -> Fa# 0 | C22: =IF(ISBLANK(D22),"",C21+1) -> 10 | D22: 1131 | E22: 1 | F22: 3.7 | G22: 2 | H22: SP-M | I22: =IF(ISBLANK(D22),"",IF(F22>0,AU22/AT22,AM22)) -> 0.60612926 | J22: =IF(ISBLANK(D22),"",IF(AQ22,"","]"&AO22&" -- "&AP22&"[")) | K22: =IF(ISBLANK(D22),"",BA22) -> -0.084334533 | L22: =IF(ISBLANK(D22),"",IF(F22>0,BF22,BF22)) -> 9.1613638e-05 | M22: =IF(ISBLANK(D22),"",IF(F22>0,"-",N22/(2^(1/12)-1))) -> - | N22: =IF(ISBLANK(D22),"",IF(F22>0,"-",1.5*L22)) -> - | O22: =IF(ISBLANK(D22),"",IF(F22>0,AU22,AK22)) -> 835.09459 | P22: =IF(ISBLANK(D22),"",IF(F22>0,AU22*G22,AL22)) -> 1670.1892 | Q22: 0.6 | R22: =IF(ISBLANK(D22),"",AT22*Q22) -> 826.65 | S22: =IF(ISBLANK(D22),"",AJ22) -> 3.6810864 | T22: =IF(ISBLANK(F22),"",ROUND(S22*10*G22,0)/10/G22) -> 3.7 | U22: =IF(F22>0,(AJ22-E22)/2,"") -> 1.3405432 | V22: =IF(F22>0,AN22,"") -> 1.4543001 | W22: =IF(F22>0,IF(U22<Paramètres!$B$5,"!!!",""),"") | X22: =IF(U22<>"",IF(U22/3>=Paramètres!$B$5,(S22-E22)/2/3,""),"") -> 0.44684773 | Y22: =IF(U22<>"",IF(U22/3>=Paramètres!$B$5,AV22,""),"") -> 0.4906388 | Z22: =IF(X22<>"",Y22*2,"") -> 0.98127761 | AC22: =INDEX('Charge de rupture par diamètre'!$C$1:$AC$1,AR22) -> Stephen Paulello France | AD22: =IF(ISBLANK(D22),"-",$A$4/16 * 2^((C22-1)/12)) -> 46.249303 | AE22: =AF22/(AF$9*SQRT(1+$L22*AF$9^2)) -> 160.07016 | AF22: =AG34 -> 320.19897 | AG22: =$AE22*AG$9*SQRT(1+$G22*AG$9^2) -> 277.24964 | AH22: =IF(AND(C22>12,F10="",AD22>$A$4),AH10*2*(1+N10),IF(AD22>=$A$4/2,AD22,AD22)) -> 46.249303 | AI22: =IF(AND(C22>12,F10="",AD22>$A$4),AH10*2*(1+N10),IF(AD22>=$A$4/2,AD22,AH34/2/(1+N22))) -> #VALUE! | AJ22: =IF(Q22>0,((R22*10^12/PI()/A22^2/D22^2-Paramètres!$B$7*E22^2)*4/PI()/Paramètres!$B$8+E22^2)^0.5,"") -> 3.6810864 | AK22: =PI()*Paramètres!$B$7*(E22*A22*D22)^2/10^12 -> 67.4769 | AL22: =AK22*G22 -> 134.9538 | AM22: =AK22/AT22 -> 0.048976157 | AN22: =(-E22+0.1*Paramètres!$B$7/E22/Paramètres!$B$8/PI()*(AW22^2-E22^2)+(E22^2+3.8*Paramètres!$B$7/Paramètres!$B$8/PI()*(AW22^2-E22^2))^0.5)/2 -> 1.4543001 | AO22: =VLOOKUP(C22,Paramètres!$C$30:$F$37,2,1) -> 0.5 | AP22: =VLOOKUP(C22,Paramètres!$C$30:$F$37,4,1) -> 0.65 | AQ22: =AND(I22>=AO22,I22<=AP22) -> TRUE | AR22: =HLOOKUP(H22,'Charge de rupture par diamètre'!$D$16:$AC$17,2,0) -> 3 | AS22: =VLOOKUP(E22,'Charge de rupture par diamètre'!$C$16:$AC$53,AR22,1) -> 1837 | AT22: =AS22*Paramètres!$B$9 -> 1377.75 | AU22: =PI()*A22^2*D22^2*(Paramètres!$B$7*E22^2+Paramètres!$B$8*PI()/4*(F22^2-E22^2))/10^12 -> 835.09459 | AV22: =0.183*(-E22+(E22^2+4*Paramètres!$B$7/PI()/Paramètres!$B$8*(AW22^2-E22^2))^0.5) -> 0.4906388 | AW22: =(R22/PI()/Paramètres!$B$7)^0.5/A22/D22*10^6 -> 3.5001227 | AX22: =Q22*VLOOKUP(H22,Paramètres!$B$15:$C$18,2,0)*Paramètres!$B$9 -> #N/A | AY22: =(AX22/PI()/Paramètres!$B$7)^0.5/A22/D22*10^6 -> #N/A | AZ22: =(IF(F22>0,(F22*F22 -E22*E22)/Paramètres!$B$7*Paramètres!$B$8,0)+E22*E22)*D22*G22 -> 35025.672 | BA22: =-1+AZ22/AZ21 -> -0.084334533 | BB22: =IF(F22>0,"",0.234*Paramètres!$B$12*10^9*IF(F22>0,E22,E22)^2/Paramètres!$B$7/A22^2/D22^4*10^6) | BC22: 2 | BD22: =BC22*SQRT(1+L22*BC22^2)-BC22 -> 0.00036642099 | BE22: =IF(F22>0,PI()^2*Paramètres!$B$12*10^9/8/O22*(E22^4+E22^2*F22^2)*10^-12/D22^2/10^-6,"-") -> 0.0034270626 | BF22: =IF(ISBLANK(D22),"-",PI()^3*E22^4*Paramètres!$B$12*10^9/64/O22/(D22/1000)^2*10^-12) -> 9.1613638e-05 | BG22: =(Paramètres!$B$12*10^9)^0.5/Paramètres!$B$7/2/D22*1000 -> 25.31124
A23: =IF(ISBLANK(D23),"-",IF(AND($A$6,$A$4/2<AD23),AG23,AD23)) -> 48.999429 | B23: =IF(ISBLANK(D23),"",VLOOKUP(MOD(C23-Paramètres!$B$54,12)+1,Paramètres!$B$40:$C$52,2)&" "&(TRUNC((C23-Paramètres!$B$54+120)/12)-10+1)) -> Sol 0 | C23: =IF(ISBLANK(D23),"",C22+1) -> 11 | D23: 1124 | E23: 1 | F23: 3.5 | G23: 2 | H23: SP-M | I23: =IF(ISBLANK(D23),"",IF(F23>0,AU23/AT23,AM23)) -> 0.60187166 | J23: =IF(ISBLANK(D23),"",IF(AQ23,"","]"&AO23&" -- "&AP23&"[")) | K23: =IF(ISBLANK(D23),"",BA23) -> -0.11167906 | L23: =IF(ISBLANK(D23),"",IF(F23>0,BF23,BF23)) -> 9.3414454e-05 | M23: =IF(ISBLANK(D23),"",IF(F23>0,"-",N23/(2^(1/12)-1))) -> - | N23: =IF(ISBLANK(D23),"",IF(F23>0,"-",1.5*L23)) -> - | O23: =IF(ISBLANK(D23),"",IF(F23>0,AU23,AK23)) -> 829.22868 | P23: =IF(ISBLANK(D23),"",IF(F23>0,AU23*G23,AL23)) -> 1658.4574 | Q23: 0.6 | R23: =IF(ISBLANK(D23),"",AT23*Q23) -> 826.65 | S23: =IF(ISBLANK(D23),"",AJ23) -> 3.4945023 | T23: =IF(ISBLANK(F23),"",ROUND(S23*10*G23,0)/10/G23) -> 3.5 | U23: =IF(F23>0,(AJ23-E23)/2,"") -> 1.2472512 | V23: =IF(F23>0,AN23,"") -> 1.3468201 | W23: =IF(F23>0,IF(U23<Paramètres!$B$5,"!!!",""),"") | X23: =IF(U23<>"",IF(U23/3>=Paramètres!$B$5,(S23-E23)/2/3,""),"") -> 0.41575039 | Y23: =IF(U23<>"",IF(U23/3>=Paramètres!$B$5,AV23,""),"") -> 0.45649393 | Z23: =IF(X23<>"",Y23*2,"") -> 0.91298786 | AC23: =INDEX('Charge de rupture par diamètre'!$C$1:$AC$1,AR23) -> Stephen Paulello France | AD23: =IF(ISBLANK(D23),"-",$A$4/16 * 2^((C23-1)/12)) -> 48.999429 | AE23: =AF23/(AF$9*SQRT(1+$L23*AF$9^2)) -> 169.59538 | AF23: =AG35 -> 339.25413 | AG23: =$AE23*AG$9*SQRT(1+$G23*AG$9^2) -> 293.74782 | AH23: =IF(AND(C23>12,F11="",AD23>$A$4),AH11*2*(1+N11),IF(AD23>=$A$4/2,AD23,AD23)) -> 48.999429 | AI23: =IF(AND(C23>12,F11="",AD23>$A$4),AH11*2*(1+N11),IF(AD23>=$A$4/2,AD23,AH35/2/(1+N23))) -> #VALUE! | AJ23: =IF(Q23>0,((R23*10^12/PI()/A23^2/D23^2-Paramètres!$B$7*E23^2)*4/PI()/Paramètres!$B$8+E23^2)^0.5,"") -> 3.4945023 | AK23: =PI()*Paramètres!$B$7*(E23*A23*D23)^2/10^12 -> 74.805615 | AL23: =AK23*G23 -> 149.61123 | AM23: =AK23/AT23 -> 0.054295493 | AN23: =(-E23+0.1*Paramètres!$B$7/E23/Paramètres!$B$8/PI()*(AW23^2-E23^2)+(E23^2+3.8*Paramètres!$B$7/Paramètres!$B$8/PI()*(AW23^2-E23^2))^0.5)/2 -> 1.3468201 | AO23: =VLOOKUP(C23,Paramètres!$C$30:$F$37,2,1) -> 0.5 | AP23: =VLOOKUP(C23,Paramètres!$C$30:$F$37,4,1) -> 0.65 | AQ23: =AND(I23>=AO23,I23<=AP23) -> TRUE | AR23: =HLOOKUP(H23,'Charge de rupture par diamètre'!$D$16:$AC$17,2,0) -> 3 | AS23: =VLOOKUP(E23,'Charge de rupture par diamètre'!$C$16:$AC$53,AR23,1) -> 1837 | AT23: =AS23*Paramètres!$B$9 -> 1377.75 | AU23: =PI()*A23^2*D23^2*(Paramètres!$B$7*E23^2+Paramètres!$B$8*PI()/4*(F23^2-E23^2))/10^12 -> 829.22868 | AV23: =0.183*(-E23+(E23^2+4*Paramètres!$B$7/PI()/Paramètres!$B$8*(AW23^2-E23^2))^0.5) -> 0.45649393 | AW23: =(R23/PI()/Paramètres!$B$7)^0.5/A23/D23*10^6 -> 3.3242504 | AX23: =Q23*VLOOKUP(H23,Paramètres!$B$15:$C$18,2,0)*Paramètres!$B$9 -> #N/A | AY23: =(AX23/PI()/Paramètres!$B$7)^0.5/A23/D23*10^6 -> #N/A | AZ23: =(IF(F23>0,(F23*F23 -E23*E23)/Paramètres!$B$7*Paramètres!$B$8,0)+E23*E23)*D23*G23 -> 31114.038 | BA23: =-1+AZ23/AZ22 -> -0.11167906 | BB23: =IF(F23>0,"",0.234*Paramètres!$B$12*10^9*IF(F23>0,E23,E23)^2/Paramètres!$B$7/A23^2/D23^4*10^6) | BC23: 2 | BD23: =BC23*SQRT(1+L23*BC23^2)-BC23 -> 0.00037362292 | BE23: =IF(F23>0,PI()^2*Paramètres!$B$12*10^9/8/O23*(E23^4+E23^2*F23^2)*10^-12/D23^2/10^-6,"-") -> 0.0031518829 | BF23: =IF(ISBLANK(D23),"-",PI()^3*E23^4*Paramètres!$B$12*10^9/64/O23/(D23/1000)^2*10^-12) -> 9.3414454e-05 | BG23: =(Paramètres!$B$12*10^9)^0.5/Paramètres!$B$7/2/D23*1000 -> 25.468873
A24: =IF(ISBLANK(D24),"-",IF(AND($A$6,$A$4/2<AD24),AG24,AD24)) -> 51.913087 | B24: =IF(ISBLANK(D24),"",VLOOKUP(MOD(C24-Paramètres!$B$54,12)+1,Paramètres!$B$40:$C$52,2)&" "&(TRUNC((C24-Paramètres!$B$54+120)/12)-10+1)) -> Sol# 0 | C24: =IF(ISBLANK(D24),"",C23+1) -> 12 | D24: 1115 | E24: 1 | F24: 3.3 | G24: 2 | H24: SP-M | I24: =IF(ISBLANK(D24),"",IF(F24>0,AU24/AT24,AM24)) -> 0.59168532 | J24: =IF(ISBLANK(D24),"",IF(AQ24,"","]"&AO24&" -- "&AP24&"[")) | K24: =IF(ISBLANK(D24),"",BA24) -> -0.11926371 | L24: =IF(ISBLANK(D24),"",IF(F24>0,BF24,BF24)) -> 9.6562848e-05 | M24: =IF(ISBLANK(D24),"",IF(F24>0,"-",N24/(2^(1/12)-1))) -> - | N24: =IF(ISBLANK(D24),"",IF(F24>0,"-",1.5*L24)) -> - | O24: =IF(ISBLANK(D24),"",IF(F24>0,AU24,AK24)) -> 815.19445 | P24: =IF(ISBLANK(D24),"",IF(F24>0,AU24*G24,AL24)) -> 1630.3889 | Q24: 0.6 | R24: =IF(ISBLANK(D24),"",AT24*Q24) -> 826.65 | S24: =IF(ISBLANK(D24),"",AJ24) -> 3.32335 | T24: =IF(ISBLANK(F24),"",ROUND(S24*10*G24,0)/10/G24) -> 3.3 | U24: =IF(F24>0,(AJ24-E24)/2,"") -> 1.161675 | V24: =IF(F24>0,AN24,"") -> 1.249013 | W24: =IF(F24>0,IF(U24<Paramètres!$B$5,"!!!",""),"") | X24: =IF(U24<>"",IF(U24/3>=Paramètres!$B$5,(S24-E24)/2/3,""),"") -> 0.387225 | Y24: =IF(U24<>"",IF(U24/3>=Paramètres!$B$5,AV24,""),"") -> 0.42517305 | Z24: =IF(X24<>"",Y24*2,"") -> 0.85034611 | AC24: =INDEX('Charge de rupture par diamètre'!$C$1:$AC$1,AR24) -> Stephen Paulello France | AD24: =IF(ISBLANK(D24),"-",$A$4/16 * 2^((C24-1)/12)) -> 51.913087 | AE24: =AF24/(AF$9*SQRT(1+$L24*AF$9^2)) -> 179.67684 | AF24: =AG36 -> 359.42307 | AG24: =$AE24*AG$9*SQRT(1+$G24*AG$9^2) -> 311.20941 | AH24: =IF(AND(C24>12,F12="",AD24>$A$4),AH12*2*(1+N12),IF(AD24>=$A$4/2,AD24,AD24)) -> 51.913087 | AI24: =IF(AND(C24>12,F12="",AD24>$A$4),AH12*2*(1+N12),IF(AD24>=$A$4/2,AD24,AH36/2/(1+N24))) -> #VALUE! | AJ24: =IF(Q24>0,((R24*10^12/PI()/A24^2/D24^2-Paramètres!$B$7*E24^2)*4/PI()/Paramètres!$B$8+E24^2)^0.5,"") -> 3.32335 | AK24: =PI()*Paramètres!$B$7*(E24*A24*D24)^2/10^12 -> 82.627189 | AL24: =AK24*G24 -> 165.25438 | AM24: =AK24/AT24 -> 0.059972556 | AN24: =(-E24+0.1*Paramètres!$B$7/E24/Paramètres!$B$8/PI()*(AW24^2-E24^2)+(E24^2+3.8*Paramètres!$B$7/Paramètres!$B$8/PI()*(AW24^2-E24^2))^0.5)/2 -> 1.249013 | AO24: =VLOOKUP(C24,Paramètres!$C$30:$F$37,2,1) -> 0.5 | AP24: =VLOOKUP(C24,Paramètres!$C$30:$F$37,4,1) -> 0.65 | AQ24: =AND(I24>=AO24,I24<=AP24) -> TRUE | AR24: =HLOOKUP(H24,'Charge de rupture par diamètre'!$D$16:$AC$17,2,0) -> 3 | AS24: =VLOOKUP(E24,'Charge de rupture par diamètre'!$C$16:$AC$53,AR24,1) -> 1837 | AT24: =AS24*Paramètres!$B$9 -> 1377.75 | AU24: =PI()*A24^2*D24^2*(Paramètres!$B$7*E24^2+Paramètres!$B$8*PI()/4*(F24^2-E24^2))/10^12 -> 815.19445 | AV24: =0.183*(-E24+(E24^2+4*Paramètres!$B$7/PI()/Paramètres!$B$8*(AW24^2-E24^2))^0.5) -> 0.42517305 | AW24: =(R24/PI()/Paramètres!$B$7)^0.5/A24/D24*10^6 -> 3.1630011 | AX24: =Q24*VLOOKUP(H24,Paramètres!$B$15:$C$18,2,0)*Paramètres!$B$9 -> #N/A | AY24: =(AX24/PI()/Paramètres!$B$7)^0.5/A24/D24*10^6 -> #N/A | AZ24: =(IF(F24>0,(F24*F24 -E24*E24)/Paramètres!$B$7*Paramètres!$B$8,0)+E24*E24)*D24*G24 -> 27403.263 | BA24: =-1+AZ24/AZ23 -> -0.11926371 | BB24: =IF(F24>0,"",0.234*Paramètres!$B$12*10^9*IF(F24>0,E24,E24)^2/Paramètres!$B$7/A24^2/D24^4*10^6) | BC24: 2 | BD24: =BC24*SQRT(1+L24*BC24^2)-BC24 -> 0.0003862141 | BE24: =IF(F24>0,PI()^2*Paramètres!$B$12*10^9/8/O24*(E24^4+E24^2*F24^2)*10^-12/D24^2/10^-6,"-") -> 0.0029236948 | BF24: =IF(ISBLANK(D24),"-",PI()^3*E24^4*Paramètres!$B$12*10^9/64/O24/(D24/1000)^2*10^-12) -> 9.6562848e-05 | BG24: =(Paramètres!$B$12*10^9)^0.5/Paramètres!$B$7/2/D24*1000 -> 25.674451
A25: =IF(ISBLANK(D25),"-",IF(AND($A$6,$A$4/2<AD25),AG25,AD25)) -> 55 | B25: =IF(ISBLANK(D25),"",VLOOKUP(MOD(C25-Paramètres!$B$54,12)+1,Paramètres!$B$40:$C$52,2)&" "&(TRUNC((C25-Paramètres!$B$54+120)/12)-10+1)) -> La 0 | C25: =IF(ISBLANK(D25),"",C24+1) -> 13 | D25: 1106 | E25: 1 | F25: 3.15 | G25: 2 | H25: SP-M | I25: =IF(ISBLANK(D25),"",IF(F25>0,AU25/AT25,AM25)) -> 0.59601942 | J25: =IF(ISBLANK(D25),"",IF(AQ25,"","]"&AO25&" -- "&AP25&"[")) | K25: =IF(ISBLANK(D25),"",BA25) -> -0.097211656 | L25: =IF(ISBLANK(D25),"",IF(F25>0,BF25,BF25)) -> 9.7427134e-05 | M25: =IF(ISBLANK(D25),"",IF(F25>0,"-",N25/(2^(1/12)-1))) -> - | N25: =IF(ISBLANK(D25),"",IF(F25>0,"-",1.5*L25)) -> - | O25: =IF(ISBLANK(D25),"",IF(F25>0,AU25,AK25)) -> 821.16576 | P25: =IF(ISBLANK(D25),"",IF(F25>0,AU25*G25,AL25)) -> 1642.3315 | Q25: 0.6 | R25: =IF(ISBLANK(D25),"",AT25*Q25) -> 826.65 | S25: =IF(ISBLANK(D25),"",AJ25) -> 3.1606233 | T25: =IF(ISBLANK(F25),"",ROUND(S25*10*G25,0)/10/G25) -> 3.15 | U25: =IF(F25>0,(AJ25-E25)/2,"") -> 1.0803117 | V25: =IF(F25>0,AN25,"") -> 1.1567189 | W25: =IF(F25>0,IF(U25<Paramètres!$B$5,"!!!",""),"") | X25: =IF(U25<>"",IF(U25/3>=Paramètres!$B$5,(S25-E25)/2/3,""),"") -> 0.36010389 | Y25: =IF(U25<>"",IF(U25/3>=Paramètres!$B$5,AV25,""),"") -> 0.39539407 | Z25: =IF(X25<>"",Y25*2,"") -> 0.79078814 | AC25: =INDEX('Charge de rupture par diamètre'!$C$1:$AC$1,AR25) -> Stephen Paulello France | AD25: =IF(ISBLANK(D25),"-",$A$4/16 * 2^((C25-1)/12)) -> 55 | AE25: =AF25/(AF$9*SQRT(1+$L25*AF$9^2)) -> 95.192779 | AF25: =AG37 -> 190.42265 | AG25: =$AE25*AG$9*SQRT(1+$G25*AG$9^2) -> 164.87873 | AH25: =IF(AND(C25>12,F13="",AD25>$A$4),AH13*2*(1+N13),IF(AD25>=$A$4/2,AD25,AD25)) -> 55 | AI25: =IF(AND(C25>12,F13="",AD25>$A$4),AH13*2*(1+N13),IF(AD25>=$A$4/2,AD25,AH37/2/(1+N25))) -> #VALUE! | AJ25: =IF(Q25>0,((R25*10^12/PI()/A25^2/D25^2-Paramètres!$B$7*E25^2)*4/PI()/Paramètres!$B$8+E25^2)^0.5,"") -> 3.1606233 | AK25: =PI()*Paramètres!$B$7*(E25*A25*D25)^2/10^12 -> 91.254683 | AL25: =AK25*G25 -> 182.50937 | AM25: =AK25/AT25 -> 0.066234573 | AN25: =(-E25+0.1*Paramètres!$B$7/E25/Paramètres!$B$8/PI()*(AW25^2-E25^2)+(E25^2+3.8*Paramètres!$B$7/Paramètres!$B$8/PI()*(AW25^2-E25^2))^0.5)/2 -> 1.1567189 | AO25: =VLOOKUP(C25,Paramètres!$C$30:$F$37,2,1) -> 0.5 | AP25: =VLOOKUP(C25,Paramètres!$C$30:$F$37,4,1) -> 0.65 | AQ25: =AND(I25>=AO25,I25<=AP25) -> TRUE | AR25: =HLOOKUP(H25,'Charge de rupture par diamètre'!$D$16:$AC$17,2,0) -> 3 | AS25: =VLOOKUP(E25,'Charge de rupture par diamètre'!$C$16:$AC$53,AR25,1) -> 1837 | AT25: =AS25*Paramètres!$B$9 -> 1377.75 | AU25: =PI()*A25^2*D25^2*(Paramètres!$B$7*E25^2+Paramètres!$B$8*PI()/4*(F25^2-E25^2))/10^12 -> 821.16576 | AV25: =0.183*(-E25+(E25^2+4*Paramètres!$B$7/PI()/Paramètres!$B$8*(AW25^2-E25^2))^0.5) -> 0.39539407 | AW25: =(R25/PI()/Paramètres!$B$7)^0.5/A25/D25*10^6 -> 3.0097696 | AX25: =Q25*VLOOKUP(H25,Paramètres!$B$15:$C$18,2,0)*Paramètres!$B$9 -> #N/A | AY25: =(AX25/PI()/Paramètres!$B$7)^0.5/A25/D25*10^6 -> #N/A | AZ25: =(IF(F25>0,(F25*F25 -E25*E25)/Paramètres!$B$7*Paramètres!$B$8,0)+E25*E25)*D25*G25 -> 24739.346 | BA25: =-1+AZ25/AZ24 -> -0.097211656 | BB25: =IF(F25>0,"",0.234*Paramètres!$B$12*10^9*IF(F25>0,E25,E25)^2/Paramètres!$B$7/A25^2/D25^4*10^6) | BC25: 2 | BD25: =BC25*SQRT(1+L25*BC25^2)-BC25 -> 0.00038967058 | BE25: =IF(F25>0,PI()^2*Paramètres!$B$12*10^9/8/O25*(E25^4+E25^2*F25^2)*10^-12/D25^2/10^-6,"-") -> 0.0027098303 | BF25: =IF(ISBLANK(D25),"-",PI()^3*E25^4*Paramètres!$B$12*10^9/64/O25/(D25/1000)^2*10^-12) -> 9.7427134e-05 | BG25: =(Paramètres!$B$12*10^9)^0.5/Paramètres!$B$7/2/D25*1000 -> 25.883375
... A40: =IF(ISBLANK(D40),"-",IF(AND($A$6,$A$4/2<AD40),AG40,AD40)) -> 130.81278 | B40: =IF(ISBLANK(D40),"",VLOOKUP(MOD(C40-Paramètres!$B$54,12)+1,Paramètres!$B$40:$C$52,2)&" "&(TRUNC((C40-Paramètres!$B$54+120)/12)-10+1)) -> Do 2 | C40: =IF(ISBLANK(D40),"",C39+1) -> 28 | D40: 896 | E40: 1 | F40: 1.6 | G40: 2 | H40: SP-M | I40: =IF(ISBLANK(D40),"",IF(F40>0,AU40/AT40,AM40)) -> 0.58979298 | J40: =IF(ISBLANK(D40),"",IF(AQ40,"","]"&AO40&" -- "&AP40&"[")) | K40: =IF(ISBLANK(D40),"",BA40) -> -0.089956472 | L40: =IF(ISBLANK(D40),"",IF(F40>0,BF40,BF40)) -> 0.0001500151 | M40: =IF(ISBLANK(D40),"",IF(F40>0,"-",N40/(2^(1/12)-1))) -> - | N40: =IF(ISBLANK(D40),"",IF(F40>0,"-",1.5*L40)) -> - | O40: =IF(ISBLANK(D40),"",IF(F40>0,AU40,AK40)) -> 812.58728 | P40: =IF(ISBLANK(D40),"",IF(F40>0,AU40*G40,AL40)) -> 1625.1746 | Q40: 0.6 | R40: =IF(ISBLANK(D40),"",AT40*Q40) -> 826.65 | S40: =IF(ISBLANK(D40),"",AJ40) -> 1.6144047 | T40: =IF(ISBLANK(F40),"",ROUND(S40*10*G40,0)/10/G40) -> 1.6 | U40: =IF(F40>0,(AJ40-E40)/2,"") -> 0.30720236 | V40: =IF(F40>0,AN40,"") -> 0.31474655 | W40: =IF(F40>0,IF(U40<Paramètres!$B$5,"!!!",""),"") | X40: =IF(U40<>"",IF(U40/3>=Paramètres!$B$5,(S40-E40)/2/3,""),"") | Y40: =IF(U40<>"",IF(U40/3>=Paramètres!$B$5,AV40,""),"") | Z40: =IF(X40<>"",Y40*2,"") | AC40: =INDEX('Charge de rupture par diamètre'!$C$1:$AC$1,AR40) -> Stephen Paulello France | AD40: =IF(ISBLANK(D40),"-",$A$4/16 * 2^((C40-1)/12)) -> 130.81278 | AE40: =AF40/(AF$9*SQRT(1+$L40*AF$9^2)) -> 130.74686 | AF40: =AG52 -> 261.57216 | AG40: =$AE40*AG$9*SQRT(1+$G40*AG$9^2) -> 226.4602 | AH40: =IF(AND(C40>12,F28="",AD40>$A$4),AH28*2*(1+N28),IF(AD40>=$A$4/2,AD40,AD40)) -> 130.81278 | AI40: =IF(AND(C40>12,F28="",AD40>$A$4),AH28*2*(1+N28),IF(AD40>=$A$4/2,AD40,AH52/2/(1+N40))) -> #VALUE! | AJ40: =IF(Q40>0,((R40*10^12/PI()/A40^2/D40^2-Paramètres!$B$7*E40^2)*4/PI()/Paramètres!$B$8+E40^2)^0.5,"") -> 1.6144047 | AK40: =PI()*Paramètres!$B$7*(E40*A40*D40)^2/10^12 -> 338.79416 | AL40: =AK40*G40 -> 677.58832 | AM40: =AK40/AT40 -> 0.24590395 | AN40: =(-E40+0.1*Paramètres!$B$7/E40/Paramètres!$B$8/PI()*(AW40^2-E40^2)+(E40^2+3.8*Paramètres!$B$7/Paramètres!$B$8/PI()*(AW40^2-E40^2))^0.5)/2 -> 0.31474655 | AO40: =VLOOKUP(C40,Paramètres!$C$30:$F$37,2,1) -> 0.5 | AP40: =VLOOKUP(C40,Paramètres!$C$30:$F$37,4,1) -> 0.65 | AQ40: =AND(I40>=AO40,I40<=AP40) -> TRUE | AR40: =HLOOKUP(H40,'Charge de rupture par diamètre'!$D$16:$AC$17,2,0) -> 3 | AS40: =VLOOKUP(E40,'Charge de rupture par diamètre'!$C$16:$AC$53,AR40,1) -> 1837 | AT40: =AS40*Paramètres!$B$9 -> 1377.75 | AU40: =PI()*A40^2*D40^2*(Paramètres!$B$7*E40^2+Paramètres!$B$8*PI()/4*(F40^2-E40^2))/10^12 -> 812.58728 | AV40: =0.183*(-E40+(E40^2+4*Paramètres!$B$7/PI()/Paramètres!$B$8*(AW40^2-E40^2))^0.5) -> 0.11243606 | AW40: =(R40/PI()/Paramètres!$B$7)^0.5/A40/D40*10^6 -> 1.5620426 | AX40: =Q40*VLOOKUP(H40,Paramètres!$B$15:$C$18,2,0)*Paramètres!$B$9 -> #N/A | AY40: =(AX40/PI()/Paramètres!$B$7)^0.5/A40/D40*10^6 -> #N/A | AZ40: =(IF(F40>0,(F40*F40 -E40*E40)/Paramètres!$B$7*Paramètres!$B$8,0)+E40*E40)*D40*G40 -> 4982.8101 | BA40: =-1+AZ40/AZ39 -> -0.089956472 | BB40: =IF(F40>0,"",0.234*Paramètres!$B$12*10^9*IF(F40>0,E40,E40)^2/Paramètres!$B$7/A40^2/D40^4*10^6) | BC40: 2 | BD40: =BC40*SQRT(1+L40*BC40^2)-BC40 -> 0.00059997041 | BE40: =IF(F40>0,PI()^2*Paramètres!$B$12*10^9/8/O40*(E40^4+E40^2*F40^2)*10^-12/D40^2/10^-6,"-") -> 0.0013599567 | BF40: =IF(ISBLANK(D40),"-",PI()^3*E40^4*Paramètres!$B$12*10^9/64/O40/(D40/1000)^2*10^-12) -> 0.0001500151 | BG40: =(Paramètres!$B$12*10^9)^0.5/Paramètres!$B$7/2/D40*1000 -> 31.949791
A41: =IF(ISBLANK(D41),"-",IF(AND($A$6,$A$4/2<AD41),AG41,AD41)) -> 138.59132 | B41: =IF(ISBLANK(D41),"",VLOOKUP(MOD(C41-Paramètres!$B$54,12)+1,Paramètres!$B$40:$C$52,2)&" "&(TRUNC((C41-Paramètres!$B$54+120)/12)-10+1)) -> Do# 2 | C41: =IF(ISBLANK(D41),"",C40+1) -> 29 | D41: 1010 | E41: 1.15 | G41: 3 | H41: SP-1 | I41: =IF(ISBLANK(D41),"",IF(F41>0,AU41/AT41,AM41)) -> 0.56204298 | J41: =IF(ISBLANK(D41),"",IF(AQ41,"","]"&AO41&" -- "&AP41&"[")) | K41: =IF(ISBLANK(D41),"",BA41) -> -0.19580018 | L41: =IF(ISBLANK(D41),"",IF(F41>0,BF41,BF41)) -> 0.00026256669 | M41: =IF(ISBLANK(D41),"",IF(F41>0,"-",N41/(2^(1/12)-1))) -> 0.0066234367 | N41: =IF(ISBLANK(D41),"",IF(F41>0,"-",1.5*L41)) -> 0.00039385004 | O41: =IF(ISBLANK(D41),"",IF(F41>0,AU41,AK41)) -> 639.04287 | P41: =IF(ISBLANK(D41),"",IF(F41>0,AU41*G41,AL41)) -> 1917.1286 | Q41: 0.55 | R41: =IF(ISBLANK(D41),"",AT41*Q41) -> 625.35 | S41: =IF(ISBLANK(D41),"",AJ41) -> 1.1361732 | T41: =IF(ISBLANK(F41),"",ROUND(S41*10*G41,0)/10/G41) | U41: =IF(F41>0,(AJ41-E41)/2,"") | V41: =IF(F41>0,AN41,"") | W41: =IF(F41>0,IF(U41<Paramètres!$B$5,"!!!",""),"") | X41: =IF(U41<>"",IF(U41/3>=Paramètres!$B$5,(S41-E41)/2/3,""),"") | Y41: =IF(U41<>"",IF(U41/3>=Paramètres!$B$5,AV41,""),"") | Z41: =IF(X41<>"",Y41*2,"") | AC41: =INDEX('Charge de rupture par diamètre'!$C$1:$AC$1,AR41) -> Stephen Paulello France | AD41: =IF(ISBLANK(D41),"-",$A$4/16 * 2^((C41-1)/12)) -> 138.59132 | AE41: =AF41/(AF$9*SQRT(1+$L41*AF$9^2)) -> 138.49346 | AF41: =AG53 -> 277.13233 | AG41: =$AE41*AG$9*SQRT(1+$G41*AG$9^2) -> 276.98692 | AH41: =IF(AND(C41>12,F29="",AD41>$A$4),AH29*2*(1+N29),IF(AD41>=$A$4/2,AD41,AD41)) -> 138.59132 | AI41: =IF(AND(C41>12,F29="",AD41>$A$4),AH29*2*(1+N29),IF(AD41>=$A$4/2,AD41,AH53/2/(1+N41))) -> 138.53675 | AJ41: =IF(Q41>0,((R41*10^12/PI()/A41^2/D41^2-Paramètres!$B$7*E41^2)*4/PI()/Paramètres!$B$8+E41^2)^0.5,"") -> 1.1361732 | AK41: =PI()*Paramètres!$B$7*(E41*A41*D41)^2/10^12 -> 639.04287 | AL41: =AK41*G41 -> 1917.1286 | AM41: =AK41/AT41 -> 0.56204298 | AN41: =(-E41+0.1*Paramètres!$B$7/E41/Paramètres!$B$8/PI()*(AW41^2-E41^2)+(E41^2+3.8*Paramètres!$B$7/Paramètres!$B$8/PI()*(AW41^2-E41^2))^0.5)/2 -> -0.0069093417 | AO41: =VLOOKUP(C41,Paramètres!$C$30:$F$37,2,1) -> 0.5 | AP41: =VLOOKUP(C41,Paramètres!$C$30:$F$37,4,1) -> 0.65 | AQ41: =AND(I41>=AO41,I41<=AP41) -> TRUE | AR41: =HLOOKUP(H41,'Charge de rupture par diamètre'!$D$16:$AC$17,2,0) -> 5 | AS41: =VLOOKUP(E41,'Charge de rupture par diamètre'!$C$16:$AC$53,AR41,1) -> 1516 | AT41: =AS41*Paramètres!$B$9 -> 1137 | AU41: =PI()*A41^2*D41^2*(Paramètres!$B$7*E41^2+Paramètres!$B$8*PI()/4*(F41^2-E41^2))/10^12 -> 66.170036 | AV41: =0.183*(-E41+(E41^2+4*Paramètres!$B$7/PI()/Paramètres!$B$8*(AW41^2-E41^2))^0.5) -> -0.0025303105 | AW41: =(R41/PI()/Paramètres!$B$7)^0.5/A41/D41*10^6 -> 1.1376127 | AX41: =Q41*VLOOKUP(H41,Paramètres!$B$15:$C$18,2,0)*Paramètres!$B$9 -> #N/A | AY41: =(AX41/PI()/Paramètres!$B$7)^0.5/A41/D41*10^6 -> #N/A | AZ41: =(IF(F41>0,(F41*F41 -E41*E41)/Paramètres!$B$7*Paramètres!$B$8,0)+E41*E41)*D41*G41 -> 4007.175 | BA41: =-1+AZ41/AZ40 -> -0.19580018 | BB41: =IF(F41>0,"",0.234*Paramètres!$B$12*10^9*IF(F41>0,E41,E41)^2/Paramètres!$B$7/A41^2/D41^4*10^6) -> 0.00039841504 | BC41: 2 | BD41: =BC41*SQRT(1+L41*BC41^2)-BC41 -> 0.0010499912 | BE41: =IF(F41>0,PI()^2*Paramètres!$B$12*10^9/8/O41*(E41^4+E41^2*F41^2)*10^-12/D41^2/10^-6,"-") -> - | BF41: =IF(ISBLANK(D41),"-",PI()^3*E41^4*Paramètres!$B$12*10^9/64/O41/(D41/1000)^2*10^-12) -> 0.00026256669 | BG41: =(Paramètres!$B$12*10^9)^0.5/Paramètres!$B$7/2/D41*1000 -> 28.343577
A42: =IF(ISBLANK(D42),"-",IF(AND($A$6,$A$4/2<AD42),AG42,AD42)) -> 146.83238 | B42: =IF(ISBLANK(D42),"",VLOOKUP(MOD(C42-Paramètres!$B$54,12)+1,Paramètres!$B$40:$C$52,2)&" "&(TRUNC((C42-Paramètres!$B$54+120)/12)-10+1)) -> Ré 2 | C42: =IF(ISBLANK(D42),"",C41+1) -> 30 | D42: 990 | E42: 1.15 | G42: 3 | H42: SP-1 | I42: =IF(ISBLANK(D42),"",IF(F42>0,AU42/AT42,AM42)) -> 0.60613426 | J42: =IF(ISBLANK(D42),"",IF(AQ42,"","]"&AO42&" -- "&AP42&"[")) | K42: =IF(ISBLANK(D42),"",BA42) -> -0.01980198 | L42: =IF(ISBLANK(D42),"",IF(F42>0,BF42,BF42)) -> 0.00025340355 | M42: =IF(ISBLANK(D42),"",IF(F42>0,"-",N42/(2^(1/12)-1))) -> 0.0063922896 | N42: =IF(ISBLANK(D42),"",IF(F42>0,"-",1.5*L42)) -> 0.00038010532 | O42: =IF(ISBLANK(D42),"",IF(F42>0,AU42,AK42)) -> 689.17466 | P42: =IF(ISBLANK(D42),"",IF(F42>0,AU42*G42,AL42)) -> 2067.524 | Q42: 0.55 | R42: =IF(ISBLANK(D42),"",AT42*Q42) -> 625.35 | S42: =IF(ISBLANK(D42),"",AJ42) -> 1.0889794 | T42: =IF(ISBLANK(F42),"",ROUND(S42*10*G42,0)/10/G42) | U42: =IF(F42>0,(AJ42-E42)/2,"") | V42: =IF(F42>0,AN42,"") | W42: =IF(F42>0,IF(U42<Paramètres!$B$5,"!!!",""),"") | X42: =IF(U42<>"",IF(U42/3>=Paramètres!$B$5,(S42-E42)/2/3,""),"") | Y42: =IF(U42<>"",IF(U42/3>=Paramètres!$B$5,AV42,""),"") | Z42: =IF(X42<>"",Y42*2,"") | AC42: =INDEX('Charge de rupture par diamètre'!$C$1:$AC$1,AR42) -> Stephen Paulello France | AD42: =IF(ISBLANK(D42),"-",$A$4/16 * 2^((C42-1)/12)) -> 146.83238 | AE42: =AF42/(AF$9*SQRT(1+$L42*AF$9^2)) -> 146.73472 | AF42: =AG54 -> 293.61814 | AG42: =$AE42*AG$9*SQRT(1+$G42*AG$9^2) -> 293.46945 | AH42: =IF(AND(C42>12,F30="",AD42>$A$4),AH30*2*(1+N30),IF(AD42>=$A$4/2,AD42,AD42)) -> 146.83238 | AI42: =IF(AND(C42>12,F30="",AD42>$A$4),AH30*2*(1+N30),IF(AD42>=$A$4/2,AD42,AH54/2/(1+N42))) -> 146.77659 | AJ42: =IF(Q42>0,((R42*10^12/PI()/A42^2/D42^2-Paramètres!$B$7*E42^2)*4/PI()/Paramètres!$B$8+E42^2)^0.5,"") -> 1.0889794 | AK42: =PI()*Paramètres!$B$7*(E42*A42*D42)^2/10^12 -> 689.17466 | AL42: =AK42*G42 -> 2067.524 | AM42: =AK42/AT42 -> 0.60613426 | AN42: =(-E42+0.1*Paramètres!$B$7/E42/Paramètres!$B$8/PI()*(AW42^2-E42^2)+(E42^2+3.8*Paramètres!$B$7/Paramètres!$B$8/PI()*(AW42^2-E42^2))^0.5)/2 -> -0.030429343 | AO42: =VLOOKUP(C42,Paramètres!$C$30:$F$37,2,1) -> 0.5 | AP42: =VLOOKUP(C42,Paramètres!$C$30:$F$37,4,1) -> 0.65 | AQ42: =AND(I42>=AO42,I42<=AP42) -> TRUE | AR42: =HLOOKUP(H42,'Charge de rupture par diamètre'!$D$16:$AC$17,2,0) -> 5 | AS42: =VLOOKUP(E42,'Charge de rupture par diamètre'!$C$16:$AC$53,AR42,1) -> 1516 | AT42: =AS42*Paramètres!$B$9 -> 1137 | AU42: =PI()*A42^2*D42^2*(Paramètres!$B$7*E42^2+Paramètres!$B$8*PI()/4*(F42^2-E42^2))/10^12 -> 71.360959 | AV42: =0.183*(-E42+(E42^2+4*Paramètres!$B$7/PI()/Paramètres!$B$8*(AW42^2-E42^2))^0.5) -> -0.011166772 | AW42: =(R42/PI()/Paramètres!$B$7)^0.5/A42/D42*10^6 -> 1.0954556 | AX42: =Q42*VLOOKUP(H42,Paramètres!$B$15:$C$18,2,0)*Paramètres!$B$9 -> #N/A | AY42: =(AX42/PI()/Paramètres!$B$7)^0.5/A42/D42*10^6 -> #N/A | AZ42: =(IF(F42>0,(F42*F42 -E42*E42)/Paramètres!$B$7*Paramètres!$B$8,0)+E42*E42)*D42*G42 -> 3927.825 | BA42: =-1+AZ42/AZ41 -> -0.01980198 | BB42: =IF(F42>0,"",0.234*Paramètres!$B$12*10^9*IF(F42>0,E42,E42)^2/Paramètres!$B$7/A42^2/D42^4*10^6) -> 0.000384511 | BC42: 2 | BD42: =BC42*SQRT(1+L42*BC42^2)-BC42 -> 0.0010133575 | BE42: =IF(F42>0,PI()^2*Paramètres!$B$12*10^9/8/O42*(E42^4+E42^2*F42^2)*10^-12/D42^2/10^-6,"-") -> - | BF42: =IF(ISBLANK(D42),"-",PI()^3*E42^4*Paramètres!$B$12*10^9/64/O42/(D42/1000)^2*10^-12) -> 0.00025340355 | BG42: =(Paramètres!$B$12*10^9)^0.5/Paramètres!$B$7/2/D42*1000 -> 28.916175
